Workbook

Sheet Mo_Phong_Tung_Buoc
A1: BẢNG THEO DÕI QUÁ TRÌNH TÍNH TOÁN PHÉP NHÂN ĐA THỨC TRONG GF(2^4)
A2: Mô phỏng trực tiếp từng câu lệnh trong hàm C gf24_multiply() — Thay đổi giá trị tại cột C (ô viền xanh) để xem kết quả cập nhật tức thì
A4: 1. THAM SỐ ĐẦU VÀO CỦA CHƯƠNG TRÌNH (NHẬP DỮ LIỆU TẠI CỘT C) | I4: 2. KẾT QUẢ ĐẦU RA TỔNG HỢP (R = A ⊗ B mod m)
A5: Tham số toán học | B5: Tên biến trong C | C5: Giá trị (Nhập) | D5: Mã Hex | E5: Dạng nhị phân | F5: Biểu diễn đa thức | G5: Hướng dẫn nhập | I5: Thập phân | J5: Mã Hex | K5: Nhị phân 4-bit | L5: Đa thức kết quả R(x) | M5: Đẳng thức kiểm chứng trên GF(2^4)
A6: Đa thức nhân thứ nhất A(x) | B6: a | C6: 10 | D6: =INDEX(Bang_Tra_Cuu!$B$5:$B$20, C6+1) | E6: =MOD(INT(C6/8),2)&MOD(INT(C6/4),2)&MOD(INT(C6/2),2)&MOD(C6,2) | F6: =INDEX(Bang_Tra_Cuu!$D$5:$D$20, C6+1) | G6: Nhập số nguyên 0 .. 15 | I6: =H15 | J6: =INDEX(Bang_Tra_Cuu!$B$5:$B$20, H15+1) | K6: =I15 | L6: =INDEX(Bang_Tra_Cuu!$D$5:$D$20, H15+1) | M6: ="(" & F6 & ") ⊗ (" & F7 & ") mod (" & F8 & ") = " & L6
A7: Đa thức nhân thứ hai B(x) | B7: b | C7: 5 | D7: =INDEX(Bang_Tra_Cuu!$B$5:$B$20, C7+1) | E7: =MOD(INT(C7/8),2)&MOD(INT(C7/4),2)&MOD(INT(C7/2),2)&MOD(C7,2) | F7: =INDEX(Bang_Tra_Cuu!$D$5:$D$20, C7+1) | G7: Nhập số nguyên 0 .. 15
A8: Đa thức tối giản m(x) | B8: mod_poly | C8: 19 | D8: =INDEX(Bang_Tra_Cuu!$B$24:$B$26, MATCH(C8, Bang_Tra_Cuu!$A$24:$A$26, 0)) | E8: =MOD(INT(C8/16),2)&MOD(INT(C8/8),2)&MOD(INT(C8/4),2)&MOD(INT(C8/2),2)&MOD(C8,2) | F8: =INDEX(Bang_Tra_Cuu!$D$24:$D$26, MATCH(C8, Bang_Tra_Cuu!$A$24:$A$26, 0)) | G8: Chọn từ danh sách: 19, 25, 31
A10: 3. BẢNG THEO DÕI TRẠNG THÁI BIẾN QUA 4 VÒNG LẶP (for i = 0; i < 4; i++)
A11: Bước lặp (i) | B11: a đầu vào (a_in) | C11: a_in (Nhị phân) | D11: b đầu vào (b_in) | E11: b_in (Nhị phân) | F11: result đầu (result_in) | G11: Bit cuối b (b & 1) | H11: result sau XOR (result mới) | I11: result mới (Nhị phân) | J11: Dịch trái a (a << 1) | K11: a << 1 (5-bit) | L11: Tràn bậc 4? (a & 16) | M11: a cuối bước (a_out) | N11: Dịch phải b (b >> 1) | O11: Giải thích câu lệnh C thực thi ở bước i
A12: 0 | B12: =C6 | C12: =MOD(INT(B12/8),2)&MOD(INT(B12/4),2)&MOD(INT(B12/2),2)&MOD(B12,2) | D12: =C7 | E12: =MOD(INT(D12/8),2)&MOD(INT(D12/4),2)&MOD(INT(D12/2),2)&MOD(D12,2) | F12: 0 | G12: =MOD(D12, 2) | H12: =IF(G12=1, (MOD(INT(F12/8)+INT(B12/8),2)*8+MOD(INT(F12/4)+INT(B12/4),2)*4+MOD(INT(F12/2)+INT(B12/2),2)*2+MOD(F12+B12,2)), F12) | I12: =MOD(INT(H12/8),2)&MOD(INT(H12/4),2)&MOD(INT(H12/2),2)&MOD(H12,2) | J12: =B12*2 | K12: =MOD(INT(J12/16),2)&MOD(INT(J12/8),2)&MOD(INT(J12/4),2)&MOD(INT(J12/2),2)&MOD(J12,2) | L12: =IF(J12>=16, 1, 0) | M12: =IF(L12=1, (MOD(INT(J12/16)+INT($C$8/16),2)*16+MOD(INT(J12/8)+INT($C$8/8),2)*8+MOD(INT(J12/4)+INT($C$8/4),2)*4+MOD(INT(J12/2)+INT($C$8/2),2)*2+MOD(J12+$C$8,2)), J12) | N12: =INT(D12/2) | O12: =IF(G12=1, "b&1=1 -> result ^= a ("&F12&"^"&B12&"="&H12&"); ", "b&1=0 -> Giữ result="&H12&"; ")&IF(L12=1, "a<<1="&J12&" (>=16, tràn) -> a ^= m => "&M12, "a<<1="&J12&" (<16, ko tràn) => a="&M12)
A13: 1 | B13: =M12 | C13: =MOD(INT(B13/8),2)&MOD(INT(B13/4),2)&MOD(INT(B13/2),2)&MOD(B13,2) | D13: =N12 | E13: =MOD(INT(D13/8),2)&MOD(INT(D13/4),2)&MOD(INT(D13/2),2)&MOD(D13,2) | F13: =H12 | G13: =MOD(D13, 2) | H13: =IF(G13=1, (MOD(INT(F13/8)+INT(B13/8),2)*8+MOD(INT(F13/4)+INT(B13/4),2)*4+MOD(INT(F13/2)+INT(B13/2),2)*2+MOD(F13+B13,2)), F13) | I13: =MOD(INT(H13/8),2)&MOD(INT(H13/4),2)&MOD(INT(H13/2),2)&MOD(H13,2) | J13: =B13*2 | K13: =MOD(INT(J13/16),2)&MOD(INT(J13/8),2)&MOD(INT(J13/4),2)&MOD(INT(J13/2),2)&MOD(J13,2) | L13: =IF(J13>=16, 1, 0) | M13: =IF(L13=1, (MOD(INT(J13/16)+INT($C$8/16),2)*16+MOD(INT(J13/8)+INT($C$8/8),2)*8+MOD(INT(J13/4)+INT($C$8/4),2)*4+MOD(INT(J13/2)+INT($C$8/2),2)*2+MOD(J13+$C$8,2)), J13) | N13: =INT(D13/2) | O13: =IF(G13=1, "b&1=1 -> result ^= a ("&F13&"^"&B13&"="&H13&"); ", "b&1=0 -> Giữ result="&H13&"; ")&IF(L13=1, "a<<1="&J13&" (>=16, tràn) -> a ^= m => "&M13, "a<<1="&J13&" (<16, ko tràn) => a="&M13)
A14: 2 | B14: =M13 | C14: =MOD(INT(B14/8),2)&MOD(INT(B14/4),2)&MOD(INT(B14/2),2)&MOD(B14,2) | D14: =N13 | E14: =MOD(INT(D14/8),2)&MOD(INT(D14/4),2)&MOD(INT(D14/2),2)&MOD(D14,2) | F14: =H13 | G14: =MOD(D14, 2) | H14: =IF(G14=1, (MOD(INT(F14/8)+INT(B14/8),2)*8+MOD(INT(F14/4)+INT(B14/4),2)*4+MOD(INT(F14/2)+INT(B14/2),2)*2+MOD(F14+B14,2)), F14) | I14: =MOD(INT(H14/8),2)&MOD(INT(H14/4),2)&MOD(INT(H14/2),2)&MOD(H14,2) | J14: =B14*2 | K14: =MOD(INT(J14/16),2)&MOD(INT(J14/8),2)&MOD(INT(J14/4),2)&MOD(INT(J14/2),2)&MOD(J14,2) | L14: =IF(J14>=16, 1, 0) | M14: =IF(L14=1, (MOD(INT(J14/16)+INT($C$8/16),2)*16+MOD(INT(J14/8)+INT($C$8/8),2)*8+MOD(INT(J14/4)+INT($C$8/4),2)*4+MOD(INT(J14/2)+INT($C$8/2),2)*2+MOD(J14+$C$8,2)), J14) | N14: =INT(D14/2) | O14: =IF(G14=1, "b&1=1 -> result ^= a ("&F14&"^"&B14&"="&H14&"); ", "b&1=0 -> Giữ result="&H14&"; ")&IF(L14=1, "a<<1="&J14&" (>=16, tràn) -> a ^= m => "&M14, "a<<1="&J14&" (<16, ko tràn) => a="&M14)
A15: 3 | B15: =M14 | C15: =MOD(INT(B15/8),2)&MOD(INT(B15/4),2)&MOD(INT(B15/2),2)&MOD(B15,2) | D15: =N14 | E15: =MOD(INT(D15/8),2)&MOD(INT(D15/4),2)&MOD(INT(D15/2),2)&MOD(D15,2) | F15: =H14 | G15: =MOD(D15, 2) | H15: =IF(G15=1, (MOD(INT(F15/8)+INT(B15/8),2)*8+MOD(INT(F15/4)+INT(B15/4),2)*4+MOD(INT(F15/2)+INT(B15/2),2)*2+MOD(F15+B15,2)), F15) | I15: =MOD(INT(H15/8),2)&MOD(INT(H15/4),2)&MOD(INT(H15/2),2)&MOD(H15,2) | J15: =B15*2 | K15: =MOD(INT(J15/16),2)&MOD(INT(J15/8),2)&MOD(INT(J15/4),2)&MOD(INT(J15/2),2)&MOD(J15,2) | L15: =IF(J15>=16, 1, 0) | M15: =IF(L15=1, (MOD(INT(J15/16)+INT($C$8/16),2)*16+MOD(INT(J15/8)+INT($C$8/8),2)*8+MOD(INT(J15/4)+INT($C$8/4),2)*4+MOD(INT(J15/2)+INT($C$8/2),2)*2+MOD(J15+$C$8,2)), J15) | N15: =INT(D15/2) | O15: =IF(G15=1, "b&1=1 -> result ^= a ("&F15&"^"&B15&"="&H15&"); ", "b&1=0 -> Giữ result="&H15&"; ")&IF(L15=1, "a<<1="&J15&" (>=16, tràn) -> a ^= m => "&M15, "a<<1="&J15&" (<16, ko tràn) => a="&M15)
A16: TỔNG SỐ LẦN KÍCH HOẠT NHÁNH ĐIỀU KIỆN (if) TRONG 4 VÒNG LẶP: | G16: =SUM(G12:G15) | H16: =H15 | I16: =I15 | J16: =MAX(J12:J15) | K16: Max(a<<1) | L16: =SUM(L12:L15) | M16: =M15 | N16: =N15 | O16: ="Tổng cộng: " & G16 & " lần cộng XOR vào result, " & L16 & " lần hạ bậc XOR với đa thức tối giản m(x)."

Sheet Kich_Ban_Kiem_Thu
A1: ĐỐI CHIẾU 3 KỊCH BẢN KIỂM THỬ TRONG CHƯƠNG TRÌNH C (main.c)
A2: Mỗi bảng dưới đây khớp chính xác với kết quả in ra màn hình console của hàm gf24_print_trace_table() trong file gf24.c
A4: KỊCH BẢN 1: Ví dụ minh họa cơ bản — A(x) = x^3 + x (10) nhân B(x) = x^2 + 1 (5) mod (x^4 + x + 1) | L4: 10 | M4: 5 | N4: 19
A5: Bước (i) | B5: a_in | C5: a_in (Bin) | D5: b_in | E5: b_in (Bin) | F5: res_in | G5: b & 1 | H5: res_mới | I5: res_mới (Bin) | J5: a << 1 | K5: a<<1 (5b) | L5: Tràn? | M5: a_out | N5: b_out
A6: 0 | B6: =L4 | C6: =MOD(INT(B6/8),2)&MOD(INT(B6/4),2)&MOD(INT(B6/2),2)&MOD(B6,2) | D6: =M4 | E6: =MOD(INT(D6/8),2)&MOD(INT(D6/4),2)&MOD(INT(D6/2),2)&MOD(D6,2) | F6: 0 | G6: =MOD(D6,2) | H6: =IF(G6=1, (MOD(INT(F6/8)+INT(B6/8),2)*8+MOD(INT(F6/4)+INT(B6/4),2)*4+MOD(INT(F6/2)+INT(B6/2),2)*2+MOD(F6+B6,2)), F6) | I6: =MOD(INT(H6/8),2)&MOD(INT(H6/4),2)&MOD(INT(H6/2),2)&MOD(H6,2) | J6: =B6*2 | K6: =MOD(INT(J6/16),2)&MOD(INT(J6/8),2)&MOD(INT(J6/4),2)&MOD(INT(J6/2),2)&MOD(J6,2) | L6: =IF(J6>=16, 1, 0) | M6: =IF(L6=1, (MOD(INT(J6/16)+INT($N$4/16),2)*16+MOD(INT(J6/8)+INT($N$4/8),2)*8+MOD(INT(J6/4)+INT($N$4/4),2)*4+MOD(INT(J6/2)+INT($N$4/2),2)*2+MOD(J6+$N$4,2)), J6) | N6: =INT(D6/2)
A7: 1 | B7: =M6 | C7: =MOD(INT(B7/8),2)&MOD(INT(B7/4),2)&MOD(INT(B7/2),2)&MOD(B7,2) | D7: =N6 | E7: =MOD(INT(D7/8),2)&MOD(INT(D7/4),2)&MOD(INT(D7/2),2)&MOD(D7,2) | F7: =H6 | G7: =MOD(D7,2) | H7: =IF(G7=1, (MOD(INT(F7/8)+INT(B7/8),2)*8+MOD(INT(F7/4)+INT(B7/4),2)*4+MOD(INT(F7/2)+INT(B7/2),2)*2+MOD(F7+B7,2)), F7) | I7: =MOD(INT(H7/8),2)&MOD(INT(H7/4),2)&MOD(INT(H7/2),2)&MOD(H7,2) | J7: =B7*2 | K7: =MOD(INT(J7/16),2)&MOD(INT(J7/8),2)&MOD(INT(J7/4),2)&MOD(INT(J7/2),2)&MOD(J7,2) | L7: =IF(J7>=16, 1, 0) | M7: =IF(L7=1, (MOD(INT(J7/16)+INT($N$4/16),2)*16+MOD(INT(J7/8)+INT($N$4/8),2)*8+MOD(INT(J7/4)+INT($N$4/4),2)*4+MOD(INT(J7/2)+INT($N$4/2),2)*2+MOD(J7+$N$4,2)), J7) | N7: =INT(D7/2)
A8: 2 | B8: =M7 | C8: =MOD(INT(B8/8),2)&MOD(INT(B8/4),2)&MOD(INT(B8/2),2)&MOD(B8,2) | D8: =N7 | E8: =MOD(INT(D8/8),2)&MOD(INT(D8/4),2)&MOD(INT(D8/2),2)&MOD(D8,2) | F8: =H7 | G8: =MOD(D8,2) | H8: =IF(G8=1, (MOD(INT(F8/8)+INT(B8/8),2)*8+MOD(INT(F8/4)+INT(B8/4),2)*4+MOD(INT(F8/2)+INT(B8/2),2)*2+MOD(F8+B8,2)), F8) | I8: =MOD(INT(H8/8),2)&MOD(INT(H8/4),2)&MOD(INT(H8/2),2)&MOD(H8,2) | J8: =B8*2 | K8: =MOD(INT(J8/16),2)&MOD(INT(J8/8),2)&MOD(INT(J8/4),2)&MOD(INT(J8/2),2)&MOD(J8,2) | L8: =IF(J8>=16, 1, 0) | M8: =IF(L8=1, (MOD(INT(J8/16)+INT($N$4/16),2)*16+MOD(INT(J8/8)+INT($N$4/8),2)*8+MOD(INT(J8/4)+INT($N$4/4),2)*4+MOD(INT(J8/2)+INT($N$4/2),2)*2+MOD(J8+$N$4,2)), J8) | N8: =INT(D8/2)
A9: 3 | B9: =M8 | C9: =MOD(INT(B9/8),2)&MOD(INT(B9/4),2)&MOD(INT(B9/2),2)&MOD(B9,2) | D9: =N8 | E9: =MOD(INT(D9/8),2)&MOD(INT(D9/4),2)&MOD(INT(D9/2),2)&MOD(D9,2) | F9: =H8 | G9: =MOD(D9,2) | H9: =IF(G9=1, (MOD(INT(F9/8)+INT(B9/8),2)*8+MOD(INT(F9/4)+INT(B9/4),2)*4+MOD(INT(F9/2)+INT(B9/2),2)*2+MOD(F9+B9,2)), F9) | I9: =MOD(INT(H9/8),2)&MOD(INT(H9/4),2)&MOD(INT(H9/2),2)&MOD(H9,2) | J9: =B9*2 | K9: =MOD(INT(J9/16),2)&MOD(INT(J9/8),2)&MOD(INT(J9/4),2)&MOD(INT(J9/2),2)&MOD(J9,2) | L9: =IF(J9>=16, 1, 0) | M9: =IF(L9=1, (MOD(INT(J9/16)+INT($N$4/16),2)*16+MOD(INT(J9/8)+INT($N$4/8),2)*8+MOD(INT(J9/4)+INT($N$4/4),2)*4+MOD(INT(J9/2)+INT($N$4/2),2)*2+MOD(J9+$N$4,2)), J9) | N9: =INT(D9/2)
A10: KẾT QUẢ CUỐI CÙNG R(x) = | H10: =H9 | I10: =I9 | J10: ="Đa thức: " & INDEX(Bang_Tra_Cuu!$D$5:$D$20, H10+1) & " (Hex: " & INDEX(Bang_Tra_Cuu!$B$5:$B$20, H10+1) & ")"
A13: KỊCH BẢN 2: Kiểm chứng cặp nghịch đảo nhân — A(x) = x^2 + 1 (5) nhân B(x) = x^3 + x + 1 (11) => Kết quả = 1 | L13: 5 | M13: 11 | N13: 19
A14: Bước (i) | B14: a_in | C14: a_in (Bin) | D14: b_in | E14: b_in (Bin) | F14: res_in | G14: b & 1 | H14: res_mới | I14: res_mới (Bin) | J14: a << 1 | K14: a<<1 (5b) | L14: Tràn? | M14: a_out | N14: b_out
A15: 0 | B15: =L13 | C15: =MOD(INT(B15/8),2)&MOD(INT(B15/4),2)&MOD(INT(B15/2),2)&MOD(B15,2) | D15: =M13 | E15: =MOD(INT(D15/8),2)&MOD(INT(D15/4),2)&MOD(INT(D15/2),2)&MOD(D15,2) | F15: 0 | G15: =MOD(D15,2) | H15: =IF(G15=1, (MOD(INT(F15/8)+INT(B15/8),2)*8+MOD(INT(F15/4)+INT(B15/4),2)*4+MOD(INT(F15/2)+INT(B15/2),2)*2+MOD(F15+B15,2)), F15) | I15: =MOD(INT(H15/8),2)&MOD(INT(H15/4),2)&MOD(INT(H15/2),2)&MOD(H15,2) | J15: =B15*2 | K15: =MOD(INT(J15/16),2)&MOD(INT(J15/8),2)&MOD(INT(J15/4),2)&MOD(INT(J15/2),2)&MOD(J15,2) | L15: =IF(J15>=16, 1, 0) | M15: =IF(L15=1, (MOD(INT(J15/16)+INT($N$13/16),2)*16+MOD(INT(J15/8)+INT($N$13/8),2)*8+MOD(INT(J15/4)+INT($N$13/4),2)*4+MOD(INT(J15/2)+INT($N$13/2),2)*2+MOD(J15+$N$13,2)), J15) | N15: =INT(D15/2)
A16: 1 | B16: =M15 | C16: =MOD(INT(B16/8),2)&MOD(INT(B16/4),2)&MOD(INT(B16/2),2)&MOD(B16,2) | D16: =N15 | E16: =MOD(INT(D16/8),2)&MOD(INT(D16/4),2)&MOD(INT(D16/2),2)&MOD(D16,2) | F16: =H15 | G16: =MOD(D16,2) | H16: =IF(G16=1, (MOD(INT(F16/8)+INT(B16/8),2)*8+MOD(INT(F16/4)+INT(B16/4),2)*4+MOD(INT(F16/2)+INT(B16/2),2)*2+MOD(F16+B16,2)), F16) | I16: =MOD(INT(H16/8),2)&MOD(INT(H16/4),2)&MOD(INT(H16/2),2)&MOD(H16,2) | J16: =B16*2 | K16: =MOD(INT(J16/16),2)&MOD(INT(J16/8),2)&MOD(INT(J16/4),2)&MOD(INT(J16/2),2)&MOD(J16,2) | L16: =IF(J16>=16, 1, 0) | M16: =IF(L16=1, (MOD(INT(J16/16)+INT($N$13/16),2)*16+MOD(INT(J16/8)+INT($N$13/8),2)*8+MOD(INT(J16/4)+INT($N$13/4),2)*4+MOD(INT(J16/2)+INT($N$13/2),2)*2+MOD(J16+$N$13,2)), J16) | N16: =INT(D16/2)
A17: 2 | B17: =M16 | C17: =MOD(INT(B17/8),2)&MOD(INT(B17/4),2)&MOD(INT(B17/2),2)&MOD(B17,2) | D17: =N16 | E17: =MOD(INT(D17/8),2)&MOD(INT(D17/4),2)&MOD(INT(D17/2),2)&MOD(D17,2) | F17: =H16 | G17: =MOD(D17,2) | H17: =IF(G17=1, (MOD(INT(F17/8)+INT(B17/8),2)*8+MOD(INT(F17/4)+INT(B17/4),2)*4+MOD(INT(F17/2)+INT(B17/2),2)*2+MOD(F17+B17,2)), F17) | I17: =MOD(INT(H17/8),2)&MOD(INT(H17/4),2)&MOD(INT(H17/2),2)&MOD(H17,2) | J17: =B17*2 | K17: =MOD(INT(J17/16),2)&MOD(INT(J17/8),2)&MOD(INT(J17/4),2)&MOD(INT(J17/2),2)&MOD(J17,2) | L17: =IF(J17>=16, 1, 0) | M17: =IF(L17=1, (MOD(INT(J17/16)+INT($N$13/16),2)*16+MOD(INT(J17/8)+INT($N$13/8),2)*8+MOD(INT(J17/4)+INT($N$13/4),2)*4+MOD(INT(J17/2)+INT($N$13/2),2)*2+MOD(J17+$N$13,2)), J17) | N17: =INT(D17/2)
A18: 3 | B18: =M17 | C18: =MOD(INT(B18/8),2)&MOD(INT(B18/4),2)&MOD(INT(B18/2),2)&MOD(B18,2) | D18: =N17 | E18: =MOD(INT(D18/8),2)&MOD(INT(D18/4),2)&MOD(INT(D18/2),2)&MOD(D18,2) | F18: =H17 | G18: =MOD(D18,2) | H18: =IF(G18=1, (MOD(INT(F18/8)+INT(B18/8),2)*8+MOD(INT(F18/4)+INT(B18/4),2)*4+MOD(INT(F18/2)+INT(B18/2),2)*2+MOD(F18+B18,2)), F18) | I18: =MOD(INT(H18/8),2)&MOD(INT(H18/4),2)&MOD(INT(H18/2),2)&MOD(H18,2) | J18: =B18*2 | K18: =MOD(INT(J18/16),2)&MOD(INT(J18/8),2)&MOD(INT(J18/4),2)&MOD(INT(J18/2),2)&MOD(J18,2) | L18: =IF(J18>=16, 1, 0) | M18: =IF(L18=1, (MOD(INT(J18/16)+INT($N$13/16),2)*16+MOD(INT(J18/8)+INT($N$13/8),2)*8+MOD(INT(J18/4)+INT($N$13/4),2)*4+MOD(INT(J18/2)+INT($N$13/2),2)*2+MOD(J18+$N$13,2)), J18) | N18: =INT(D18/2)
A19: KẾT QUẢ CUỐI CÙNG R(x) = | H19: =H18 | I19: =I18 | J19: ="Đa thức: " & INDEX(Bang_Tra_Cuu!$D$5:$D$20, H19+1) & " (Hex: " & INDEX(Bang_Tra_Cuu!$B$5:$B$20, H19+1) & ")"
A22: KỊCH BẢN 3: Nhân phần tử bậc cao g^9 * g^11 — A(x) = x^3 + x (10) nhân B(x) = x^3 + x^2 + x (14) => g^5 = x^2 + x (6) | L22: 10 | M22: 14 | N22: 19
A23: Bước (i) | B23: a_in | C23: a_in (Bin) | D23: b_in | E23: b_in (Bin) | F23: res_in | G23: b & 1 | H23: res_mới | I23: res_mới (Bin) | J23: a << 1 | K23: a<<1 (5b) | L23: Tràn? | M23: a_out | N23: b_out
A24: 0 | B24: =L22 | C24: =MOD(INT(B24/8),2)&MOD(INT(B24/4),2)&MOD(INT(B24/2),2)&MOD(B24,2) | D24: =M22 | E24: =MOD(INT(D24/8),2)&MOD(INT(D24/4),2)&MOD(INT(D24/2),2)&MOD(D24,2) | F24: 0 | G24: =MOD(D24,2) | H24: =IF(G24=1, (MOD(INT(F24/8)+INT(B24/8),2)*8+MOD(INT(F24/4)+INT(B24/4),2)*4+MOD(INT(F24/2)+INT(B24/2),2)*2+MOD(F24+B24,2)), F24) | I24: =MOD(INT(H24/8),2)&MOD(INT(H24/4),2)&MOD(INT(H24/2),2)&MOD(H24,2) | J24: =B24*2 | K24: =MOD(INT(J24/16),2)&MOD(INT(J24/8),2)&MOD(INT(J24/4),2)&MOD(INT(J24/2),2)&MOD(J24,2) | L24: =IF(J24>=16, 1, 0) | M24: =IF(L24=1, (MOD(INT(J24/16)+INT($N$22/16),2)*16+MOD(INT(J24/8)+INT($N$22/8),2)*8+MOD(INT(J24/4)+INT($N$22/4),2)*4+MOD(INT(J24/2)+INT($N$22/2),2)*2+MOD(J24+$N$22,2)), J24) | N24: =INT(D24/2)
A25: 1 | B25: =M24 | C25: =MOD(INT(B25/8),2)&MOD(INT(B25/4),2)&MOD(INT(B25/2),2)&MOD(B25,2) | D25: =N24 | E25: =MOD(INT(D25/8),2)&MOD(INT(D25/4),2)&MOD(INT(D25/2),2)&MOD(D25,2) | F25: =H24 | G25: =MOD(D25,2) | H25: =IF(G25=1, (MOD(INT(F25/8)+INT(B25/8),2)*8+MOD(INT(F25/4)+INT(B25/4),2)*4+MOD(INT(F25/2)+INT(B25/2),2)*2+MOD(F25+B25,2)), F25) | I25: =MOD(INT(H25/8),2)&MOD(INT(H25/4),2)&MOD(INT(H25/2),2)&MOD(H25,2) | J25: =B25*2 | K25: =MOD(INT(J25/16),2)&MOD(INT(J25/8),2)&MOD(INT(J25/4),2)&MOD(INT(J25/2),2)&MOD(J25,2) | L25: =IF(J25>=16, 1, 0) | M25: =IF(L25=1, (MOD(INT(J25/16)+INT($N$22/16),2)*16+MOD(INT(J25/8)+INT($N$22/8),2)*8+MOD(INT(J25/4)+INT($N$22/4),2)*4+MOD(INT(J25/2)+INT($N$22/2),2)*2+MOD(J25+$N$22,2)), J25) | N25: =INT(D25/2)
A26: 2 | B26: =M25 | C26: =MOD(INT(B26/8),2)&MOD(INT(B26/4),2)&MOD(INT(B26/2),2)&MOD(B26,2) | D26: =N25 | E26: =MOD(INT(D26/8),2)&MOD(INT(D26/4),2)&MOD(INT(D26/2),2)&MOD(D26,2) | F26: =H25 | G26: =MOD(D26,2) | H26: =IF(G26=1, (MOD(INT(F26/8)+INT(B26/8),2)*8+MOD(INT(F26/4)+INT(B26/4),2)*4+MOD(INT(F26/2)+INT(B26/2),2)*2+MOD(F26+B26,2)), F26) | I26: =MOD(INT(H26/8),2)&MOD(INT(H26/4),2)&MOD(INT(H26/2),2)&MOD(H26,2) | J26: =B26*2 | K26: =MOD(INT(J26/16),2)&MOD(INT(J26/8),2)&MOD(INT(J26/4),2)&MOD(INT(J26/2),2)&MOD(J26,2) | L26: =IF(J26>=16, 1, 0) | M26: =IF(L26=1, (MOD(INT(J26/16)+INT($N$22/16),2)*16+MOD(INT(J26/8)+INT($N$22/8),2)*8+MOD(INT(J26/4)+INT($N$22/4),2)*4+MOD(INT(J26/2)+INT($N$22/2),2)*2+MOD(J26+$N$22,2)), J26) | N26: =INT(D26/2)
A27: 3 | B27: =M26 | C27: =MOD(INT(B27/8),2)&MOD(INT(B27/4),2)&MOD(INT(B27/2),2)&MOD(B27,2) | D27: =N26 | E27: =MOD(INT(D27/8),2)&MOD(INT(D27/4),2)&MOD(INT(D27/2),2)&MOD(D27,2) | F27: =H26 | G27: =MOD(D27,2) | H27: =IF(G27=1, (MOD(INT(F27/8)+INT(B27/8),2)*8+MOD(INT(F27/4)+INT(B27/4),2)*4+MOD(INT(F27/2)+INT(B27/2),2)*2+MOD(F27+B27,2)), F27) | I27: =MOD(INT(H27/8),2)&MOD(INT(H27/4),2)&MOD(INT(H27/2),2)&MOD(H27,2) | J27: =B27*2 | K27: =MOD(INT(J27/16),2)&MOD(INT(J27/8),2)&MOD(INT(J27/4),2)&MOD(INT(J27/2),2)&MOD(J27,2) | L27: =IF(J27>=16, 1, 0) | M27: =IF(L27=1, (MOD(INT(J27/16)+INT($N$22/16),2)*16+MOD(INT(J27/8)+INT($N$22/8),2)*8+MOD(INT(J27/4)+INT($N$22/4),2)*4+MOD(INT(J27/2)+INT($N$22/2),2)*2+MOD(J27+$N$22,2)), J27) | N27: =INT(D27/2)
A28: KẾT QUẢ CUỐI CÙNG R(x) = | H28: =H27 | I28: =I27 | J28: ="Đa thức: " & INDEX(Bang_Tra_Cuu!$D$5:$D$20, H28+1) & " (Hex: " & INDEX(Bang_Tra_Cuu!$B$5:$B$20, H28+1) & ")"

Sheet Bang_Nhan_16x16
A1: BẢNG CỬU CHƯƠNG NHÂN TOÀN TRƯỜNG GF(2^4) (16 x 16) & KIỂM CHỨNG TÍNH CHẤT SONG ÁNH
A2: ="Đang tính tự động theo đa thức tối giản m(x) = " & Mo_Phong_Tung_Buoc!F8 & " (Ô màu xanh lá = 1 biểu thị cặp phần tử nghịch đảo nhân a * b = 1)"
A4: A \ B | B4: Đa thức | C4: 0x0 | D4: 0x1 | E4: 0x2 | F4: 0x3 | G4: 0x4 | H4: 0x5 | I4: 0x6 | J4: 0x7 | K4: 0x8 | L4: 0x9 | M4: 0xA | N4: 0xB | O4: 0xC | P4: 0xD | Q4: 0xE | R4: 0xF | T4: THỐNG KÊ TẦN SUẤT KẾT QUẢ
A5: Thập phân | B5: f(x) | C5: 0 | D5: 1 | E5: 2 | F5: 3 | G5: 4 | H5: 5 | I5: 6 | J5: 7 | K5: 8 | L5: 9 | M5: 10 | N5: 11 | O5: 12 | P5: 13 | Q5: 14 | R5: 15 | T5: Giá trị | U5: Đa thức | V5: Toàn bảng (16x16) | W5: Nhóm nhân khác 0 (15x15)
A6: 0 | B6: 0 | C6: =MOD(MOD(C$5,2)*INT(Bang_Tra_Cuu!$I$5/1)+MOD(INT(C$5/2),2)*INT(Bang_Tra_Cuu!$J$5/1)+MOD(INT(C$5/4),2)*INT(Bang_Tra_Cuu!$K$5/1)+MOD(INT(C$5/8),2)*INT(Bang_Tra_Cuu!$L$5/1),2)*1+MOD(MOD(C$5,2)*INT(Bang_Tra_Cuu!$I$5/2)+MOD(INT(C$5/2),2)*INT(Bang_Tra_Cuu!$J$5/2)+MOD(INT(C$5/4),2)*INT(Bang_Tra_Cuu!$K$5/2)+MOD(INT(C$5/8),2)*INT(Bang_Tra_Cuu!$L$5/2),2)*2+MOD(MOD(C$5,2)*INT(Bang_Tra_Cuu!$I$5/4)+MOD(INT(C$5/2),2)*INT(Bang_Tra_Cuu!$J$5/4)+MOD(INT(C$5/4),2)*INT(Bang_Tra_Cuu!$K$5/4)+MOD(INT(C$5/8),2)*INT(Bang_Tra_Cuu!$L$5/4),2)*4+MOD(MOD(C$5,2)*INT(Bang_Tra_Cuu!$I$5/8)+MOD(INT(C$5/2),2)*INT(Bang_Tra_Cuu!$J$5/8)+MOD(INT(C$5/4),2)*INT(Bang_Tra_Cuu!$K$5/8)+MOD(INT(C$5/8),2)*INT(Bang_Tra_Cuu!$L$5/8),2)*8 | D6: =MOD(MOD(D$5,2)*INT(Bang_Tra_Cuu!$I$5/1)+MOD(INT(D$5/2),2)*INT(Bang_Tra_Cuu!$J$5/1)+MOD(INT(D$5/4),2)*INT(Bang_Tra_Cuu!$K$5/1)+MOD(INT(D$5/8),2)*INT(Bang_Tra_Cuu!$L$5/1),2)*1+MOD(MOD(D$5,2)*INT(Bang_Tra_Cuu!$I$5/2)+MOD(INT(D$5/2),2)*INT(Bang_Tra_Cuu!$J$5/2)+MOD(INT(D$5/4),2)*INT(Bang_Tra_Cuu!$K$5/2)+MOD(INT(D$5/8),2)*INT(Bang_Tra_Cuu!$L$5/2),2)*2+MOD(MOD(D$5,2)*INT(Bang_Tra_Cuu!$I$5/4)+MOD(INT(D$5/2),2)*INT(Bang_Tra_Cuu!$J$5/4)+MOD(INT(D$5/4),2)*INT(Bang_Tra_Cuu!$K$5/4)+MOD(INT(D$5/8),2)*INT(Bang_Tra_Cuu!$L$5/4),2)*4+MOD(MOD(D$5,2)*INT(Bang_Tra_Cuu!$I$5/8)+MOD(INT(D$5/2),2)*INT(Bang_Tra_Cuu!$J$5/8)+MOD(INT(D$5/4),2)*INT(Bang_Tra_Cuu!$K$5/8)+MOD(INT(D$5/8),2)*INT(Bang_Tra_Cuu!$L$5/8),2)*8 | E6: =MOD(MOD(E$5,2)*INT(Bang_Tra_Cuu!$I$5/1)+MOD(INT(E$5/2),2)*INT(Bang_Tra_Cuu!$J$5/1)+MOD(INT(E$5/4),2)*INT(Bang_Tra_Cuu!$K$5/1)+MOD(INT(E$5/8),2)*INT(Bang_Tra_Cuu!$L$5/1),2)*1+MOD(MOD(E$5,2)*INT(Bang_Tra_Cuu!$I$5/2)+MOD(INT(E$5/2),2)*INT(Bang_Tra_Cuu!$J$5/2)+MOD(INT(E$5/4),2)*INT(Bang_Tra_Cuu!$K$5/2)+MOD(INT(E$5/8),2)*INT(Bang_Tra_Cuu!$L$5/2),2)*2+MOD(MOD(E$5,2)*INT(Bang_Tra_Cuu!$I$5/4)+MOD(INT(E$5/2),2)*INT(Bang_Tra_Cuu!$J$5/4)+MOD(INT(E$5/4),2)*INT(Bang_Tra_Cuu!$K$5/4)+MOD(INT(E$5/8),2)*INT(Bang_Tra_Cuu!$L$5/4),2)*4+MOD(MOD(E$5,2)*INT(Bang_Tra_Cuu!$I$5/8)+MOD(INT(E$5/2),2)*INT(Bang_Tra_Cuu!$J$5/8)+MOD(INT(E$5/4),2)*INT(Bang_Tra_Cuu!$K$5/8)+MOD(INT(E$5/8),2)*INT(Bang_Tra_Cuu!$L$5/8),2)*8 | F6: =MOD(MOD(F$5,2)*INT(Bang_Tra_Cuu!$I$5/1)+MOD(INT(F$5/2),2)*INT(Bang_Tra_Cuu!$J$5/1)+MOD(INT(F$5/4),2)*INT(Bang_Tra_Cuu!$K$5/1)+MOD(INT(F$5/8),2)*INT(Bang_Tra_Cuu!$L$5/1),2)*1+MOD(MOD(F$5,2)*INT(Bang_Tra_Cuu!$I$5/2)+MOD(INT(F$5/2),2)*INT(Bang_Tra_Cuu!$J$5/2)+MOD(INT(F$5/4),2)*INT(Bang_Tra_Cuu!$K$5/2)+MOD(INT(F$5/8),2)*INT(Bang_Tra_Cuu!$L$5/2),2)*2+MOD(MOD(F$5,2)*INT(Bang_Tra_Cuu!$I$5/4)+MOD(INT(F$5/2),2)*INT(Bang_Tra_Cuu!$J$5/4)+MOD(INT(F$5/4),2)*INT(Bang_Tra_Cuu!$K$5/4)+MOD(INT(F$5/8),2)*INT(Bang_Tra_Cuu!$L$5/4),2)*4+MOD(MOD(F$5,2)*INT(Bang_Tra_Cuu!$I$5/8)+MOD(INT(F$5/2),2)*INT(Bang_Tra_Cuu!$J$5/8)+MOD(INT(F$5/4),2)*INT(Bang_Tra_Cuu!$K$5/8)+MOD(INT(F$5/8),2)*INT(Bang_Tra_Cuu!$L$5/8),2)*8 | G6: =MOD(MOD(G$5,2)*INT(Bang_Tra_Cuu!$I$5/1)+MOD(INT(G$5/2),2)*INT(Bang_Tra_Cuu!$J$5/1)+MOD(INT(G$5/4),2)*INT(Bang_Tra_Cuu!$K$5/1)+MOD(INT(G$5/8),2)*INT(Bang_Tra_Cuu!$L$5/1),2)*1+MOD(MOD(G$5,2)*INT(Bang_Tra_Cuu!$I$5/2)+MOD(INT(G$5/2),2)*INT(Bang_Tra_Cuu!$J$5/2)+MOD(INT(G$5/4),2)*INT(Bang_Tra_Cuu!$K$5/2)+MOD(INT(G$5/8),2)*INT(Bang_Tra_Cuu!$L$5/2),2)*2+MOD(MOD(G$5,2)*INT(Bang_Tra_Cuu!$I$5/4)+MOD(INT(G$5/2),2)*INT(Bang_Tra_Cuu!$J$5/4)+MOD(INT(G$5/4),2)*INT(Bang_Tra_Cuu!$K$5/4)+MOD(INT(G$5/8),2)*INT(Bang_Tra_Cuu!$L$5/4),2)*4+MOD(MOD(G$5,2)*INT(Bang_Tra_Cuu!$I$5/8)+MOD(INT(G$5/2),2)*INT(Bang_Tra_Cuu!$J$5/8)+MOD(INT(G$5/4),2)*INT(Bang_Tra_Cuu!$K$5/8)+MOD(INT(G$5/8),2)*INT(Bang_Tra_Cuu!$L$5/8),2)*8 | H6: =MOD(MOD(H$5,2)*INT(Bang_Tra_Cuu!$I$5/1)+MOD(INT(H$5/2),2)*INT(Bang_Tra_Cuu!$J$5/1)+MOD(INT(H$5/4),2)*INT(Bang_Tra_Cuu!$K$5/1)+MOD(INT(H$5/8),2)*INT(Bang_Tra_Cuu!$L$5/1),2)*1+MOD(MOD(H$5,2)*INT(Bang_Tra_Cuu!$I$5/2)+MOD(INT(H$5/2),2)*INT(Bang_Tra_Cuu!$J$5/2)+MOD(INT(H$5/4),2)*INT(Bang_Tra_Cuu!$K$5/2)+MOD(INT(H$5/8),2)*INT(Bang_Tra_Cuu!$L$5/2),2)*2+MOD(MOD(H$5,2)*INT(Bang_Tra_Cuu!$I$5/4)+MOD(INT(H$5/2),2)*INT(Bang_Tra_Cuu!$J$5/4)+MOD(INT(H$5/4),2)*INT(Bang_Tra_Cuu!$K$5/4)+MOD(INT(H$5/8),2)*INT(Bang_Tra_Cuu!$L$5/4),2)*4+MOD(MOD(H$5,2)*INT(Bang_Tra_Cuu!$I$5/8)+MOD(INT(H$5/2),2)*INT(Bang_Tra_Cuu!$J$5/8)+MOD(INT(H$5/4),2)*INT(Bang_Tra_Cuu!$K$5/8)+MOD(INT(H$5/8),2)*INT(Bang_Tra_Cuu!$L$5/8),2)*8 | I6: =MOD(MOD(I$5,2)*INT(Bang_Tra_Cuu!$I$5/1)+MOD(INT(I$5/2),2)*INT(Bang_Tra_Cuu!$J$5/1)+MOD(INT(I$5/4),2)*INT(Bang_Tra_Cuu!$K$5/1)+MOD(INT(I$5/8),2)*INT(Bang_Tra_Cuu!$L$5/1),2)*1+MOD(MOD(I$5,2)*INT(Bang_Tra_Cuu!$I$5/2)+MOD(INT(I$5/2),2)*INT(Bang_Tra_Cuu!$J$5/2)+MOD(INT(I$5/4),2)*INT(Bang_Tra_Cuu!$K$5/2)+MOD(INT(I$5/8),2)*INT(Bang_Tra_Cuu!$L$5/2),2)*2+MOD(MOD(I$5,2)*INT(Bang_Tra_Cuu!$I$5/4)+MOD(INT(I$5/2),2)*INT(Bang_Tra_Cuu!$J$5/4)+MOD(INT(I$5/4),2)*INT(Bang_Tra_Cuu!$K$5/4)+MOD(INT(I$5/8),2)*INT(Bang_Tra_Cuu!$L$5/4),2)*4+MOD(MOD(I$5,2)*INT(Bang_Tra_Cuu!$I$5/8)+MOD(INT(I$5/2),2)*INT(Bang_Tra_Cuu!$J$5/8)+MOD(INT(I$5/4),2)*INT(Bang_Tra_Cuu!$K$5/8)+MOD(INT(I$5/8),2)*INT(Bang_Tra_Cuu!$L$5/8),2)*8 | J6: =MOD(MOD(J$5,2)*INT(Bang_Tra_Cuu!$I$5/1)+MOD(INT(J$5/2),2)*INT(Bang_Tra_Cuu!$J$5/1)+MOD(INT(J$5/4),2)*INT(Bang_Tra_Cuu!$K$5/1)+MOD(INT(J$5/8),2)*INT(Bang_Tra_Cuu!$L$5/1),2)*1+MOD(MOD(J$5,2)*INT(Bang_Tra_Cuu!$I$5/2)+MOD(INT(J$5/2),2)*INT(Bang_Tra_Cuu!$J$5/2)+MOD(INT(J$5/4),2)*INT(Bang_Tra_Cuu!$K$5/2)+MOD(INT(J$5/8),2)*INT(Bang_Tra_Cuu!$L$5/2),2)*2+MOD(MOD(J$5,2)*INT(Bang_Tra_Cuu!$I$5/4)+MOD(INT(J$5/2),2)*INT(Bang_Tra_Cuu!$J$5/4)+MOD(INT(J$5/4),2)*INT(Bang_Tra_Cuu!$K$5/4)+MOD(INT(J$5/8),2)*INT(Bang_Tra_Cuu!$L$5/4),2)*4+MOD(MOD(J$5,2)*INT(Bang_Tra_Cuu!$I$5/8)+MOD(INT(J$5/2),2)*INT(Bang_Tra_Cuu!$J$5/8)+MOD(INT(J$5/4),2)*INT(Bang_Tra_Cuu!$K$5/8)+MOD(INT(J$5/8),2)*INT(Bang_Tra_Cuu!$L$5/8),2)*8 | ... R6: =MOD(MOD(R$5,2)*INT(Bang_Tra_Cuu!$I$5/1)+MOD(INT(R$5/2),2)*INT(Bang_Tra_Cuu!$J$5/1)+MOD(INT(R$5/4),2)*INT(Bang_Tra_Cuu!$K$5/1)+MOD(INT(R$5/8),2)*INT(Bang_Tra_Cuu!$L$5/1),2)*1+MOD(MOD(R$5,2)*INT(Bang_Tra_Cuu!$I$5/2)+MOD(INT(R$5/2),2)*INT(Bang_Tra_Cuu!$J$5/2)+MOD(INT(R$5/4),2)*INT(Bang_Tra_Cuu!$K$5/2)+MOD(INT(R$5/8),2)*INT(Bang_Tra_Cuu!$L$5/2),2)*2+MOD(MOD(R$5,2)*INT(Bang_Tra_Cuu!$I$5/4)+MOD(INT(R$5/2),2)*INT(Bang_Tra_Cuu!$J$5/4)+MOD(INT(R$5/4),2)*INT(Bang_Tra_Cuu!$K$5/4)+MOD(INT(R$5/8),2)*INT(Bang_Tra_Cuu!$L$5/4),2)*4+MOD(MOD(R$5,2)*INT(Bang_Tra_Cuu!$I$5/8)+MOD(INT(R$5/2),2)*INT(Bang_Tra_Cuu!$J$5/8)+MOD(INT(R$5/4),2)*INT(Bang_Tra_Cuu!$K$5/8)+MOD(INT(R$5/8),2)*INT(Bang_Tra_Cuu!$L$5/8),2)*8 | T6: 0 | U6: 0 | V6: =COUNTIF($C$6:$R$21, T6) | W6: =COUNTIF($D$7:$R$21, T6)
A7: 1 | B7: 1 | C7: =MOD(MOD(C$5,2)*INT(Bang_Tra_Cuu!$I$6/1)+MOD(INT(C$5/2),2)*INT(Bang_Tra_Cuu!$J$6/1)+MOD(INT(C$5/4),2)*INT(Bang_Tra_Cuu!$K$6/1)+MOD(INT(C$5/8),2)*INT(Bang_Tra_Cuu!$L$6/1),2)*1+MOD(MOD(C$5,2)*INT(Bang_Tra_Cuu!$I$6/2)+MOD(INT(C$5/2),2)*INT(Bang_Tra_Cuu!$J$6/2)+MOD(INT(C$5/4),2)*INT(Bang_Tra_Cuu!$K$6/2)+MOD(INT(C$5/8),2)*INT(Bang_Tra_Cuu!$L$6/2),2)*2+MOD(MOD(C$5,2)*INT(Bang_Tra_Cuu!$I$6/4)+MOD(INT(C$5/2),2)*INT(Bang_Tra_Cuu!$J$6/4)+MOD(INT(C$5/4),2)*INT(Bang_Tra_Cuu!$K$6/4)+MOD(INT(C$5/8),2)*INT(Bang_Tra_Cuu!$L$6/4),2)*4+MOD(MOD(C$5,2)*INT(Bang_Tra_Cuu!$I$6/8)+MOD(INT(C$5/2),2)*INT(Bang_Tra_Cuu!$J$6/8)+MOD(INT(C$5/4),2)*INT(Bang_Tra_Cuu!$K$6/8)+MOD(INT(C$5/8),2)*INT(Bang_Tra_Cuu!$L$6/8),2)*8 | D7: =MOD(MOD(D$5,2)*INT(Bang_Tra_Cuu!$I$6/1)+MOD(INT(D$5/2),2)*INT(Bang_Tra_Cuu!$J$6/1)+MOD(INT(D$5/4),2)*INT(Bang_Tra_Cuu!$K$6/1)+MOD(INT(D$5/8),2)*INT(Bang_Tra_Cuu!$L$6/1),2)*1+MOD(MOD(D$5,2)*INT(Bang_Tra_Cuu!$I$6/2)+MOD(INT(D$5/2),2)*INT(Bang_Tra_Cuu!$J$6/2)+MOD(INT(D$5/4),2)*INT(Bang_Tra_Cuu!$K$6/2)+MOD(INT(D$5/8),2)*INT(Bang_Tra_Cuu!$L$6/2),2)*2+MOD(MOD(D$5,2)*INT(Bang_Tra_Cuu!$I$6/4)+MOD(INT(D$5/2),2)*INT(Bang_Tra_Cuu!$J$6/4)+MOD(INT(D$5/4),2)*INT(Bang_Tra_Cuu!$K$6/4)+MOD(INT(D$5/8),2)*INT(Bang_Tra_Cuu!$L$6/4),2)*4+MOD(MOD(D$5,2)*INT(Bang_Tra_Cuu!$I$6/8)+MOD(INT(D$5/2),2)*INT(Bang_Tra_Cuu!$J$6/8)+MOD(INT(D$5/4),2)*INT(Bang_Tra_Cuu!$K$6/8)+MOD(INT(D$5/8),2)*INT(Bang_Tra_Cuu!$L$6/8),2)*8 | E7: =MOD(MOD(E$5,2)*INT(Bang_Tra_Cuu!$I$6/1)+MOD(INT(E$5/2),2)*INT(Bang_Tra_Cuu!$J$6/1)+MOD(INT(E$5/4),2)*INT(Bang_Tra_Cuu!$K$6/1)+MOD(INT(E$5/8),2)*INT(Bang_Tra_Cuu!$L$6/1),2)*1+MOD(MOD(E$5,2)*INT(Bang_Tra_Cuu!$I$6/2)+MOD(INT(E$5/2),2)*INT(Bang_Tra_Cuu!$J$6/2)+MOD(INT(E$5/4),2)*INT(Bang_Tra_Cuu!$K$6/2)+MOD(INT(E$5/8),2)*INT(Bang_Tra_Cuu!$L$6/2),2)*2+MOD(MOD(E$5,2)*INT(Bang_Tra_Cuu!$I$6/4)+MOD(INT(E$5/2),2)*INT(Bang_Tra_Cuu!$J$6/4)+MOD(INT(E$5/4),2)*INT(Bang_Tra_Cuu!$K$6/4)+MOD(INT(E$5/8),2)*INT(Bang_Tra_Cuu!$L$6/4),2)*4+MOD(MOD(E$5,2)*INT(Bang_Tra_Cuu!$I$6/8)+MOD(INT(E$5/2),2)*INT(Bang_Tra_Cuu!$J$6/8)+MOD(INT(E$5/4),2)*INT(Bang_Tra_Cuu!$K$6/8)+MOD(INT(E$5/8),2)*INT(Bang_Tra_Cuu!$L$6/8),2)*8 | F7: =MOD(MOD(F$5,2)*INT(Bang_Tra_Cuu!$I$6/1)+MOD(INT(F$5/2),2)*INT(Bang_Tra_Cuu!$J$6/1)+MOD(INT(F$5/4),2)*INT(Bang_Tra_Cuu!$K$6/1)+MOD(INT(F$5/8),2)*INT(Bang_Tra_Cuu!$L$6/1),2)*1+MOD(MOD(F$5,2)*INT(Bang_Tra_Cuu!$I$6/2)+MOD(INT(F$5/2),2)*INT(Bang_Tra_Cuu!$J$6/2)+MOD(INT(F$5/4),2)*INT(Bang_Tra_Cuu!$K$6/2)+MOD(INT(F$5/8),2)*INT(Bang_Tra_Cuu!$L$6/2),2)*2+MOD(MOD(F$5,2)*INT(Bang_Tra_Cuu!$I$6/4)+MOD(INT(F$5/2),2)*INT(Bang_Tra_Cuu!$J$6/4)+MOD(INT(F$5/4),2)*INT(Bang_Tra_Cuu!$K$6/4)+MOD(INT(F$5/8),2)*INT(Bang_Tra_Cuu!$L$6/4),2)*4+MOD(MOD(F$5,2)*INT(Bang_Tra_Cuu!$I$6/8)+MOD(INT(F$5/2),2)*INT(Bang_Tra_Cuu!$J$6/8)+MOD(INT(F$5/4),2)*INT(Bang_Tra_Cuu!$K$6/8)+MOD(INT(F$5/8),2)*INT(Bang_Tra_Cuu!$L$6/8),2)*8 | G7: =MOD(MOD(G$5,2)*INT(Bang_Tra_Cuu!$I$6/1)+MOD(INT(G$5/2),2)*INT(Bang_Tra_Cuu!$J$6/1)+MOD(INT(G$5/4),2)*INT(Bang_Tra_Cuu!$K$6/1)+MOD(INT(G$5/8),2)*INT(Bang_Tra_Cuu!$L$6/1),2)*1+MOD(MOD(G$5,2)*INT(Bang_Tra_Cuu!$I$6/2)+MOD(INT(G$5/2),2)*INT(Bang_Tra_Cuu!$J$6/2)+MOD(INT(G$5/4),2)*INT(Bang_Tra_Cuu!$K$6/2)+MOD(INT(G$5/8),2)*INT(Bang_Tra_Cuu!$L$6/2),2)*2+MOD(MOD(G$5,2)*INT(Bang_Tra_Cuu!$I$6/4)+MOD(INT(G$5/2),2)*INT(Bang_Tra_Cuu!$J$6/4)+MOD(INT(G$5/4),2)*INT(Bang_Tra_Cuu!$K$6/4)+MOD(INT(G$5/8),2)*INT(Bang_Tra_Cuu!$L$6/4),2)*4+MOD(MOD(G$5,2)*INT(Bang_Tra_Cuu!$I$6/8)+MOD(INT(G$5/2),2)*INT(Bang_Tra_Cuu!$J$6/8)+MOD(INT(G$5/4),2)*INT(Bang_Tra_Cuu!$K$6/8)+MOD(INT(G$5/8),2)*INT(Bang_Tra_Cuu!$L$6/8),2)*8 | H7: =MOD(MOD(H$5,2)*INT(Bang_Tra_Cuu!$I$6/1)+MOD(INT(H$5/2),2)*INT(Bang_Tra_Cuu!$J$6/1)+MOD(INT(H$5/4),2)*INT(Bang_Tra_Cuu!$K$6/1)+MOD(INT(H$5/8),2)*INT(Bang_Tra_Cuu!$L$6/1),2)*1+MOD(MOD(H$5,2)*INT(Bang_Tra_Cuu!$I$6/2)+MOD(INT(H$5/2),2)*INT(Bang_Tra_Cuu!$J$6/2)+MOD(INT(H$5/4),2)*INT(Bang_Tra_Cuu!$K$6/2)+MOD(INT(H$5/8),2)*INT(Bang_Tra_Cuu!$L$6/2),2)*2+MOD(MOD(H$5,2)*INT(Bang_Tra_Cuu!$I$6/4)+MOD(INT(H$5/2),2)*INT(Bang_Tra_Cuu!$J$6/4)+MOD(INT(H$5/4),2)*INT(Bang_Tra_Cuu!$K$6/4)+MOD(INT(H$5/8),2)*INT(Bang_Tra_Cuu!$L$6/4),2)*4+MOD(MOD(H$5,2)*INT(Bang_Tra_Cuu!$I$6/8)+MOD(INT(H$5/2),2)*INT(Bang_Tra_Cuu!$J$6/8)+MOD(INT(H$5/4),2)*INT(Bang_Tra_Cuu!$K$6/8)+MOD(INT(H$5/8),2)*INT(Bang_Tra_Cuu!$L$6/8),2)*8 | I7: =MOD(MOD(I$5,2)*INT(Bang_Tra_Cuu!$I$6/1)+MOD(INT(I$5/2),2)*INT(Bang_Tra_Cuu!$J$6/1)+MOD(INT(I$5/4),2)*INT(Bang_Tra_Cuu!$K$6/1)+MOD(INT(I$5/8),2)*INT(Bang_Tra_Cuu!$L$6/1),2)*1+MOD(MOD(I$5,2)*INT(Bang_Tra_Cuu!$I$6/2)+MOD(INT(I$5/2),2)*INT(Bang_Tra_Cuu!$J$6/2)+MOD(INT(I$5/4),2)*INT(Bang_Tra_Cuu!$K$6/2)+MOD(INT(I$5/8),2)*INT(Bang_Tra_Cuu!$L$6/2),2)*2+MOD(MOD(I$5,2)*INT(Bang_Tra_Cuu!$I$6/4)+MOD(INT(I$5/2),2)*INT(Bang_Tra_Cuu!$J$6/4)+MOD(INT(I$5/4),2)*INT(Bang_Tra_Cuu!$K$6/4)+MOD(INT(I$5/8),2)*INT(Bang_Tra_Cuu!$L$6/4),2)*4+MOD(MOD(I$5,2)*INT(Bang_Tra_Cuu!$I$6/8)+MOD(INT(I$5/2),2)*INT(Bang_Tra_Cuu!$J$6/8)+MOD(INT(I$5/4),2)*INT(Bang_Tra_Cuu!$K$6/8)+MOD(INT(I$5/8),2)*INT(Bang_Tra_Cuu!$L$6/8),2)*8 | J7: =MOD(MOD(J$5,2)*INT(Bang_Tra_Cuu!$I$6/1)+MOD(INT(J$5/2),2)*INT(Bang_Tra_Cuu!$J$6/1)+MOD(INT(J$5/4),2)*INT(Bang_Tra_Cuu!$K$6/1)+MOD(INT(J$5/8),2)*INT(Bang_Tra_Cuu!$L$6/1),2)*1+MOD(MOD(J$5,2)*INT(Bang_Tra_Cuu!$I$6/2)+MOD(INT(J$5/2),2)*INT(Bang_Tra_Cuu!$J$6/2)+MOD(INT(J$5/4),2)*INT(Bang_Tra_Cuu!$K$6/2)+MOD(INT(J$5/8),2)*INT(Bang_Tra_Cuu!$L$6/2),2)*2+MOD(MOD(J$5,2)*INT(Bang_Tra_Cuu!$I$6/4)+MOD(INT(J$5/2),2)*INT(Bang_Tra_Cuu!$J$6/4)+MOD(INT(J$5/4),2)*INT(Bang_Tra_Cuu!$K$6/4)+MOD(INT(J$5/8),2)*INT(Bang_Tra_Cuu!$L$6/4),2)*4+MOD(MOD(J$5,2)*INT(Bang_Tra_Cuu!$I$6/8)+MOD(INT(J$5/2),2)*INT(Bang_Tra_Cuu!$J$6/8)+MOD(INT(J$5/4),2)*INT(Bang_Tra_Cuu!$K$6/8)+MOD(INT(J$5/8),2)*INT(Bang_Tra_Cuu!$L$6/8),2)*8 | ... R7: =MOD(MOD(R$5,2)*INT(Bang_Tra_Cuu!$I$6/1)+MOD(INT(R$5/2),2)*INT(Bang_Tra_Cuu!$J$6/1)+MOD(INT(R$5/4),2)*INT(Bang_Tra_Cuu!$K$6/1)+MOD(INT(R$5/8),2)*INT(Bang_Tra_Cuu!$L$6/1),2)*1+MOD(MOD(R$5,2)*INT(Bang_Tra_Cuu!$I$6/2)+MOD(INT(R$5/2),2)*INT(Bang_Tra_Cuu!$J$6/2)+MOD(INT(R$5/4),2)*INT(Bang_Tra_Cuu!$K$6/2)+MOD(INT(R$5/8),2)*INT(Bang_Tra_Cuu!$L$6/2),2)*2+MOD(MOD(R$5,2)*INT(Bang_Tra_Cuu!$I$6/4)+MOD(INT(R$5/2),2)*INT(Bang_Tra_Cuu!$J$6/4)+MOD(INT(R$5/4),2)*INT(Bang_Tra_Cuu!$K$6/4)+MOD(INT(R$5/8),2)*INT(Bang_Tra_Cuu!$L$6/4),2)*4+MOD(MOD(R$5,2)*INT(Bang_Tra_Cuu!$I$6/8)+MOD(INT(R$5/2),2)*INT(Bang_Tra_Cuu!$J$6/8)+MOD(INT(R$5/4),2)*INT(Bang_Tra_Cuu!$K$6/8)+MOD(INT(R$5/8),2)*INT(Bang_Tra_Cuu!$L$6/8),2)*8 | T7: 1 | U7: 1 | V7: =COUNTIF($C$6:$R$21, T7) | W7: =COUNTIF($D$7:$R$21, T7)
A8: 2 | B8: x | C8: =MOD(MOD(C$5,2)*INT(Bang_Tra_Cuu!$I$7/1)+MOD(INT(C$5/2),2)*INT(Bang_Tra_Cuu!$J$7/1)+MOD(INT(C$5/4),2)*INT(Bang_Tra_Cuu!$K$7/1)+MOD(INT(C$5/8),2)*INT(Bang_Tra_Cuu!$L$7/1),2)*1+MOD(MOD(C$5,2)*INT(Bang_Tra_Cuu!$I$7/2)+MOD(INT(C$5/2),2)*INT(Bang_Tra_Cuu!$J$7/2)+MOD(INT(C$5/4),2)*INT(Bang_Tra_Cuu!$K$7/2)+MOD(INT(C$5/8),2)*INT(Bang_Tra_Cuu!$L$7/2),2)*2+MOD(MOD(C$5,2)*INT(Bang_Tra_Cuu!$I$7/4)+MOD(INT(C$5/2),2)*INT(Bang_Tra_Cuu!$J$7/4)+MOD(INT(C$5/4),2)*INT(Bang_Tra_Cuu!$K$7/4)+MOD(INT(C$5/8),2)*INT(Bang_Tra_Cuu!$L$7/4),2)*4+MOD(MOD(C$5,2)*INT(Bang_Tra_Cuu!$I$7/8)+MOD(INT(C$5/2),2)*INT(Bang_Tra_Cuu!$J$7/8)+MOD(INT(C$5/4),2)*INT(Bang_Tra_Cuu!$K$7/8)+MOD(INT(C$5/8),2)*INT(Bang_Tra_Cuu!$L$7/8),2)*8 | D8: =MOD(MOD(D$5,2)*INT(Bang_Tra_Cuu!$I$7/1)+MOD(INT(D$5/2),2)*INT(Bang_Tra_Cuu!$J$7/1)+MOD(INT(D$5/4),2)*INT(Bang_Tra_Cuu!$K$7/1)+MOD(INT(D$5/8),2)*INT(Bang_Tra_Cuu!$L$7/1),2)*1+MOD(MOD(D$5,2)*INT(Bang_Tra_Cuu!$I$7/2)+MOD(INT(D$5/2),2)*INT(Bang_Tra_Cuu!$J$7/2)+MOD(INT(D$5/4),2)*INT(Bang_Tra_Cuu!$K$7/2)+MOD(INT(D$5/8),2)*INT(Bang_Tra_Cuu!$L$7/2),2)*2+MOD(MOD(D$5,2)*INT(Bang_Tra_Cuu!$I$7/4)+MOD(INT(D$5/2),2)*INT(Bang_Tra_Cuu!$J$7/4)+MOD(INT(D$5/4),2)*INT(Bang_Tra_Cuu!$K$7/4)+MOD(INT(D$5/8),2)*INT(Bang_Tra_Cuu!$L$7/4),2)*4+MOD(MOD(D$5,2)*INT(Bang_Tra_Cuu!$I$7/8)+MOD(INT(D$5/2),2)*INT(Bang_Tra_Cuu!$J$7/8)+MOD(INT(D$5/4),2)*INT(Bang_Tra_Cuu!$K$7/8)+MOD(INT(D$5/8),2)*INT(Bang_Tra_Cuu!$L$7/8),2)*8 | E8: =MOD(MOD(E$5,2)*INT(Bang_Tra_Cuu!$I$7/1)+MOD(INT(E$5/2),2)*INT(Bang_Tra_Cuu!$J$7/1)+MOD(INT(E$5/4),2)*INT(Bang_Tra_Cuu!$K$7/1)+MOD(INT(E$5/8),2)*INT(Bang_Tra_Cuu!$L$7/1),2)*1+MOD(MOD(E$5,2)*INT(Bang_Tra_Cuu!$I$7/2)+MOD(INT(E$5/2),2)*INT(Bang_Tra_Cuu!$J$7/2)+MOD(INT(E$5/4),2)*INT(Bang_Tra_Cuu!$K$7/2)+MOD(INT(E$5/8),2)*INT(Bang_Tra_Cuu!$L$7/2),2)*2+MOD(MOD(E$5,2)*INT(Bang_Tra_Cuu!$I$7/4)+MOD(INT(E$5/2),2)*INT(Bang_Tra_Cuu!$J$7/4)+MOD(INT(E$5/4),2)*INT(Bang_Tra_Cuu!$K$7/4)+MOD(INT(E$5/8),2)*INT(Bang_Tra_Cuu!$L$7/4),2)*4+MOD(MOD(E$5,2)*INT(Bang_Tra_Cuu!$I$7/8)+MOD(INT(E$5/2),2)*INT(Bang_Tra_Cuu!$J$7/8)+MOD(INT(E$5/4),2)*INT(Bang_Tra_Cuu!$K$7/8)+MOD(INT(E$5/8),2)*INT(Bang_Tra_Cuu!$L$7/8),2)*8 | F8: =MOD(MOD(F$5,2)*INT(Bang_Tra_Cuu!$I$7/1)+MOD(INT(F$5/2),2)*INT(Bang_Tra_Cuu!$J$7/1)+MOD(INT(F$5/4),2)*INT(Bang_Tra_Cuu!$K$7/1)+MOD(INT(F$5/8),2)*INT(Bang_Tra_Cuu!$L$7/1),2)*1+MOD(MOD(F$5,2)*INT(Bang_Tra_Cuu!$I$7/2)+MOD(INT(F$5/2),2)*INT(Bang_Tra_Cuu!$J$7/2)+MOD(INT(F$5/4),2)*INT(Bang_Tra_Cuu!$K$7/2)+MOD(INT(F$5/8),2)*INT(Bang_Tra_Cuu!$L$7/2),2)*2+MOD(MOD(F$5,2)*INT(Bang_Tra_Cuu!$I$7/4)+MOD(INT(F$5/2),2)*INT(Bang_Tra_Cuu!$J$7/4)+MOD(INT(F$5/4),2)*INT(Bang_Tra_Cuu!$K$7/4)+MOD(INT(F$5/8),2)*INT(Bang_Tra_Cuu!$L$7/4),2)*4+MOD(MOD(F$5,2)*INT(Bang_Tra_Cuu!$I$7/8)+MOD(INT(F$5/2),2)*INT(Bang_Tra_Cuu!$J$7/8)+MOD(INT(F$5/4),2)*INT(Bang_Tra_Cuu!$K$7/8)+MOD(INT(F$5/8),2)*INT(Bang_Tra_Cuu!$L$7/8),2)*8 | G8: =MOD(MOD(G$5,2)*INT(Bang_Tra_Cuu!$I$7/1)+MOD(INT(G$5/2),2)*INT(Bang_Tra_Cuu!$J$7/1)+MOD(INT(G$5/4),2)*INT(Bang_Tra_Cuu!$K$7/1)+MOD(INT(G$5/8),2)*INT(Bang_Tra_Cuu!$L$7/1),2)*1+MOD(MOD(G$5,2)*INT(Bang_Tra_Cuu!$I$7/2)+MOD(INT(G$5/2),2)*INT(Bang_Tra_Cuu!$J$7/2)+MOD(INT(G$5/4),2)*INT(Bang_Tra_Cuu!$K$7/2)+MOD(INT(G$5/8),2)*INT(Bang_Tra_Cuu!$L$7/2),2)*2+MOD(MOD(G$5,2)*INT(Bang_Tra_Cuu!$I$7/4)+MOD(INT(G$5/2),2)*INT(Bang_Tra_Cuu!$J$7/4)+MOD(INT(G$5/4),2)*INT(Bang_Tra_Cuu!$K$7/4)+MOD(INT(G$5/8),2)*INT(Bang_Tra_Cuu!$L$7/4),2)*4+MOD(MOD(G$5,2)*INT(Bang_Tra_Cuu!$I$7/8)+MOD(INT(G$5/2),2)*INT(Bang_Tra_Cuu!$J$7/8)+MOD(INT(G$5/4),2)*INT(Bang_Tra_Cuu!$K$7/8)+MOD(INT(G$5/8),2)*INT(Bang_Tra_Cuu!$L$7/8),2)*8 | H8: =MOD(MOD(H$5,2)*INT(Bang_Tra_Cuu!$I$7/1)+MOD(INT(H$5/2),2)*INT(Bang_Tra_Cuu!$J$7/1)+MOD(INT(H$5/4),2)*INT(Bang_Tra_Cuu!$K$7/1)+MOD(INT(H$5/8),2)*INT(Bang_Tra_Cuu!$L$7/1),2)*1+MOD(MOD(H$5,2)*INT(Bang_Tra_Cuu!$I$7/2)+MOD(INT(H$5/2),2)*INT(Bang_Tra_Cuu!$J$7/2)+MOD(INT(H$5/4),2)*INT(Bang_Tra_Cuu!$K$7/2)+MOD(INT(H$5/8),2)*INT(Bang_Tra_Cuu!$L$7/2),2)*2+MOD(MOD(H$5,2)*INT(Bang_Tra_Cuu!$I$7/4)+MOD(INT(H$5/2),2)*INT(Bang_Tra_Cuu!$J$7/4)+MOD(INT(H$5/4),2)*INT(Bang_Tra_Cuu!$K$7/4)+MOD(INT(H$5/8),2)*INT(Bang_Tra_Cuu!$L$7/4),2)*4+MOD(MOD(H$5,2)*INT(Bang_Tra_Cuu!$I$7/8)+MOD(INT(H$5/2),2)*INT(Bang_Tra_Cuu!$J$7/8)+MOD(INT(H$5/4),2)*INT(Bang_Tra_Cuu!$K$7/8)+MOD(INT(H$5/8),2)*INT(Bang_Tra_Cuu!$L$7/8),2)*8 | I8: =MOD(MOD(I$5,2)*INT(Bang_Tra_Cuu!$I$7/1)+MOD(INT(I$5/2),2)*INT(Bang_Tra_Cuu!$J$7/1)+MOD(INT(I$5/4),2)*INT(Bang_Tra_Cuu!$K$7/1)+MOD(INT(I$5/8),2)*INT(Bang_Tra_Cuu!$L$7/1),2)*1+MOD(MOD(I$5,2)*INT(Bang_Tra_Cuu!$I$7/2)+MOD(INT(I$5/2),2)*INT(Bang_Tra_Cuu!$J$7/2)+MOD(INT(I$5/4),2)*INT(Bang_Tra_Cuu!$K$7/2)+MOD(INT(I$5/8),2)*INT(Bang_Tra_Cuu!$L$7/2),2)*2+MOD(MOD(I$5,2)*INT(Bang_Tra_Cuu!$I$7/4)+MOD(INT(I$5/2),2)*INT(Bang_Tra_Cuu!$J$7/4)+MOD(INT(I$5/4),2)*INT(Bang_Tra_Cuu!$K$7/4)+MOD(INT(I$5/8),2)*INT(Bang_Tra_Cuu!$L$7/4),2)*4+MOD(MOD(I$5,2)*INT(Bang_Tra_Cuu!$I$7/8)+MOD(INT(I$5/2),2)*INT(Bang_Tra_Cuu!$J$7/8)+MOD(INT(I$5/4),2)*INT(Bang_Tra_Cuu!$K$7/8)+MOD(INT(I$5/8),2)*INT(Bang_Tra_Cuu!$L$7/8),2)*8 | J8: =MOD(MOD(J$5,2)*INT(Bang_Tra_Cuu!$I$7/1)+MOD(INT(J$5/2),2)*INT(Bang_Tra_Cuu!$J$7/1)+MOD(INT(J$5/4),2)*INT(Bang_Tra_Cuu!$K$7/1)+MOD(INT(J$5/8),2)*INT(Bang_Tra_Cuu!$L$7/1),2)*1+MOD(MOD(J$5,2)*INT(Bang_Tra_Cuu!$I$7/2)+MOD(INT(J$5/2),2)*INT(Bang_Tra_Cuu!$J$7/2)+MOD(INT(J$5/4),2)*INT(Bang_Tra_Cuu!$K$7/2)+MOD(INT(J$5/8),2)*INT(Bang_Tra_Cuu!$L$7/2),2)*2+MOD(MOD(J$5,2)*INT(Bang_Tra_Cuu!$I$7/4)+MOD(INT(J$5/2),2)*INT(Bang_Tra_Cuu!$J$7/4)+MOD(INT(J$5/4),2)*INT(Bang_Tra_Cuu!$K$7/4)+MOD(INT(J$5/8),2)*INT(Bang_Tra_Cuu!$L$7/4),2)*4+MOD(MOD(J$5,2)*INT(Bang_Tra_Cuu!$I$7/8)+MOD(INT(J$5/2),2)*INT(Bang_Tra_Cuu!$J$7/8)+MOD(INT(J$5/4),2)*INT(Bang_Tra_Cuu!$K$7/8)+MOD(INT(J$5/8),2)*INT(Bang_Tra_Cuu!$L$7/8),2)*8 | ... R8: =MOD(MOD(R$5,2)*INT(Bang_Tra_Cuu!$I$7/1)+MOD(INT(R$5/2),2)*INT(Bang_Tra_Cuu!$J$7/1)+MOD(INT(R$5/4),2)*INT(Bang_Tra_Cuu!$K$7/1)+MOD(INT(R$5/8),2)*INT(Bang_Tra_Cuu!$L$7/1),2)*1+MOD(MOD(R$5,2)*INT(Bang_Tra_Cuu!$I$7/2)+MOD(INT(R$5/2),2)*INT(Bang_Tra_Cuu!$J$7/2)+MOD(INT(R$5/4),2)*INT(Bang_Tra_Cuu!$K$7/2)+MOD(INT(R$5/8),2)*INT(Bang_Tra_Cuu!$L$7/2),2)*2+MOD(MOD(R$5,2)*INT(Bang_Tra_Cuu!$I$7/4)+MOD(INT(R$5/2),2)*INT(Bang_Tra_Cuu!$J$7/4)+MOD(INT(R$5/4),2)*INT(Bang_Tra_Cuu!$K$7/4)+MOD(INT(R$5/8),2)*INT(Bang_Tra_Cuu!$L$7/4),2)*4+MOD(MOD(R$5,2)*INT(Bang_Tra_Cuu!$I$7/8)+MOD(INT(R$5/2),2)*INT(Bang_Tra_Cuu!$J$7/8)+MOD(INT(R$5/4),2)*INT(Bang_Tra_Cuu!$K$7/8)+MOD(INT(R$5/8),2)*INT(Bang_Tra_Cuu!$L$7/8),2)*8 | T8: 2 | U8: x | V8: =COUNTIF($C$6:$R$21, T8) | W8: =COUNTIF($D$7:$R$21, T8)
A9: 3 | B9: x + 1 | C9: =MOD(MOD(C$5,2)*INT(Bang_Tra_Cuu!$I$8/1)+MOD(INT(C$5/2),2)*INT(Bang_Tra_Cuu!$J$8/1)+MOD(INT(C$5/4),2)*INT(Bang_Tra_Cuu!$K$8/1)+MOD(INT(C$5/8),2)*INT(Bang_Tra_Cuu!$L$8/1),2)*1+MOD(MOD(C$5,2)*INT(Bang_Tra_Cuu!$I$8/2)+MOD(INT(C$5/2),2)*INT(Bang_Tra_Cuu!$J$8/2)+MOD(INT(C$5/4),2)*INT(Bang_Tra_Cuu!$K$8/2)+MOD(INT(C$5/8),2)*INT(Bang_Tra_Cuu!$L$8/2),2)*2+MOD(MOD(C$5,2)*INT(Bang_Tra_Cuu!$I$8/4)+MOD(INT(C$5/2),2)*INT(Bang_Tra_Cuu!$J$8/4)+MOD(INT(C$5/4),2)*INT(Bang_Tra_Cuu!$K$8/4)+MOD(INT(C$5/8),2)*INT(Bang_Tra_Cuu!$L$8/4),2)*4+MOD(MOD(C$5,2)*INT(Bang_Tra_Cuu!$I$8/8)+MOD(INT(C$5/2),2)*INT(Bang_Tra_Cuu!$J$8/8)+MOD(INT(C$5/4),2)*INT(Bang_Tra_Cuu!$K$8/8)+MOD(INT(C$5/8),2)*INT(Bang_Tra_Cuu!$L$8/8),2)*8 | D9: =MOD(MOD(D$5,2)*INT(Bang_Tra_Cuu!$I$8/1)+MOD(INT(D$5/2),2)*INT(Bang_Tra_Cuu!$J$8/1)+MOD(INT(D$5/4),2)*INT(Bang_Tra_Cuu!$K$8/1)+MOD(INT(D$5/8),2)*INT(Bang_Tra_Cuu!$L$8/1),2)*1+MOD(MOD(D$5,2)*INT(Bang_Tra_Cuu!$I$8/2)+MOD(INT(D$5/2),2)*INT(Bang_Tra_Cuu!$J$8/2)+MOD(INT(D$5/4),2)*INT(Bang_Tra_Cuu!$K$8/2)+MOD(INT(D$5/8),2)*INT(Bang_Tra_Cuu!$L$8/2),2)*2+MOD(MOD(D$5,2)*INT(Bang_Tra_Cuu!$I$8/4)+MOD(INT(D$5/2),2)*INT(Bang_Tra_Cuu!$J$8/4)+MOD(INT(D$5/4),2)*INT(Bang_Tra_Cuu!$K$8/4)+MOD(INT(D$5/8),2)*INT(Bang_Tra_Cuu!$L$8/4),2)*4+MOD(MOD(D$5,2)*INT(Bang_Tra_Cuu!$I$8/8)+MOD(INT(D$5/2),2)*INT(Bang_Tra_Cuu!$J$8/8)+MOD(INT(D$5/4),2)*INT(Bang_Tra_Cuu!$K$8/8)+MOD(INT(D$5/8),2)*INT(Bang_Tra_Cuu!$L$8/8),2)*8 | E9: =MOD(MOD(E$5,2)*INT(Bang_Tra_Cuu!$I$8/1)+MOD(INT(E$5/2),2)*INT(Bang_Tra_Cuu!$J$8/1)+MOD(INT(E$5/4),2)*INT(Bang_Tra_Cuu!$K$8/1)+MOD(INT(E$5/8),2)*INT(Bang_Tra_Cuu!$L$8/1),2)*1+MOD(MOD(E$5,2)*INT(Bang_Tra_Cuu!$I$8/2)+MOD(INT(E$5/2),2)*INT(Bang_Tra_Cuu!$J$8/2)+MOD(INT(E$5/4),2)*INT(Bang_Tra_Cuu!$K$8/2)+MOD(INT(E$5/8),2)*INT(Bang_Tra_Cuu!$L$8/2),2)*2+MOD(MOD(E$5,2)*INT(Bang_Tra_Cuu!$I$8/4)+MOD(INT(E$5/2),2)*INT(Bang_Tra_Cuu!$J$8/4)+MOD(INT(E$5/4),2)*INT(Bang_Tra_Cuu!$K$8/4)+MOD(INT(E$5/8),2)*INT(Bang_Tra_Cuu!$L$8/4),2)*4+MOD(MOD(E$5,2)*INT(Bang_Tra_Cuu!$I$8/8)+MOD(INT(E$5/2),2)*INT(Bang_Tra_Cuu!$J$8/8)+MOD(INT(E$5/4),2)*INT(Bang_Tra_Cuu!$K$8/8)+MOD(INT(E$5/8),2)*INT(Bang_Tra_Cuu!$L$8/8),2)*8 | F9: =MOD(MOD(F$5,2)*INT(Bang_Tra_Cuu!$I$8/1)+MOD(INT(F$5/2),2)*INT(Bang_Tra_Cuu!$J$8/1)+MOD(INT(F$5/4),2)*INT(Bang_Tra_Cuu!$K$8/1)+MOD(INT(F$5/8),2)*INT(Bang_Tra_Cuu!$L$8/1),2)*1+MOD(MOD(F$5,2)*INT(Bang_Tra_Cuu!$I$8/2)+MOD(INT(F$5/2),2)*INT(Bang_Tra_Cuu!$J$8/2)+MOD(INT(F$5/4),2)*INT(Bang_Tra_Cuu!$K$8/2)+MOD(INT(F$5/8),2)*INT(Bang_Tra_Cuu!$L$8/2),2)*2+MOD(MOD(F$5,2)*INT(Bang_Tra_Cuu!$I$8/4)+MOD(INT(F$5/2),2)*INT(Bang_Tra_Cuu!$J$8/4)+MOD(INT(F$5/4),2)*INT(Bang_Tra_Cuu!$K$8/4)+MOD(INT(F$5/8),2)*INT(Bang_Tra_Cuu!$L$8/4),2)*4+MOD(MOD(F$5,2)*INT(Bang_Tra_Cuu!$I$8/8)+MOD(INT(F$5/2),2)*INT(Bang_Tra_Cuu!$J$8/8)+MOD(INT(F$5/4),2)*INT(Bang_Tra_Cuu!$K$8/8)+MOD(INT(F$5/8),2)*INT(Bang_Tra_Cuu!$L$8/8),2)*8 | G9: =MOD(MOD(G$5,2)*INT(Bang_Tra_Cuu!$I$8/1)+MOD(INT(G$5/2),2)*INT(Bang_Tra_Cuu!$J$8/1)+MOD(INT(G$5/4),2)*INT(Bang_Tra_Cuu!$K$8/1)+MOD(INT(G$5/8),2)*INT(Bang_Tra_Cuu!$L$8/1),2)*1+MOD(MOD(G$5,2)*INT(Bang_Tra_Cuu!$I$8/2)+MOD(INT(G$5/2),2)*INT(Bang_Tra_Cuu!$J$8/2)+MOD(INT(G$5/4),2)*INT(Bang_Tra_Cuu!$K$8/2)+MOD(INT(G$5/8),2)*INT(Bang_Tra_Cuu!$L$8/2),2)*2+MOD(MOD(G$5,2)*INT(Bang_Tra_Cuu!$I$8/4)+MOD(INT(G$5/2),2)*INT(Bang_Tra_Cuu!$J$8/4)+MOD(INT(G$5/4),2)*INT(Bang_Tra_Cuu!$K$8/4)+MOD(INT(G$5/8),2)*INT(Bang_Tra_Cuu!$L$8/4),2)*4+MOD(MOD(G$5,2)*INT(Bang_Tra_Cuu!$I$8/8)+MOD(INT(G$5/2),2)*INT(Bang_Tra_Cuu!$J$8/8)+MOD(INT(G$5/4),2)*INT(Bang_Tra_Cuu!$K$8/8)+MOD(INT(G$5/8),2)*INT(Bang_Tra_Cuu!$L$8/8),2)*8 | H9: =MOD(MOD(H$5,2)*INT(Bang_Tra_Cuu!$I$8/1)+MOD(INT(H$5/2),2)*INT(Bang_Tra_Cuu!$J$8/1)+MOD(INT(H$5/4),2)*INT(Bang_Tra_Cuu!$K$8/1)+MOD(INT(H$5/8),2)*INT(Bang_Tra_Cuu!$L$8/1),2)*1+MOD(MOD(H$5,2)*INT(Bang_Tra_Cuu!$I$8/2)+MOD(INT(H$5/2),2)*INT(Bang_Tra_Cuu!$J$8/2)+MOD(INT(H$5/4),2)*INT(Bang_Tra_Cuu!$K$8/2)+MOD(INT(H$5/8),2)*INT(Bang_Tra_Cuu!$L$8/2),2)*2+MOD(MOD(H$5,2)*INT(Bang_Tra_Cuu!$I$8/4)+MOD(INT(H$5/2),2)*INT(Bang_Tra_Cuu!$J$8/4)+MOD(INT(H$5/4),2)*INT(Bang_Tra_Cuu!$K$8/4)+MOD(INT(H$5/8),2)*INT(Bang_Tra_Cuu!$L$8/4),2)*4+MOD(MOD(H$5,2)*INT(Bang_Tra_Cuu!$I$8/8)+MOD(INT(H$5/2),2)*INT(Bang_Tra_Cuu!$J$8/8)+MOD(INT(H$5/4),2)*INT(Bang_Tra_Cuu!$K$8/8)+MOD(INT(H$5/8),2)*INT(Bang_Tra_Cuu!$L$8/8),2)*8 | I9: =MOD(MOD(I$5,2)*INT(Bang_Tra_Cuu!$I$8/1)+MOD(INT(I$5/2),2)*INT(Bang_Tra_Cuu!$J$8/1)+MOD(INT(I$5/4),2)*INT(Bang_Tra_Cuu!$K$8/1)+MOD(INT(I$5/8),2)*INT(Bang_Tra_Cuu!$L$8/1),2)*1+MOD(MOD(I$5,2)*INT(Bang_Tra_Cuu!$I$8/2)+MOD(INT(I$5/2),2)*INT(Bang_Tra_Cuu!$J$8/2)+MOD(INT(I$5/4),2)*INT(Bang_Tra_Cuu!$K$8/2)+MOD(INT(I$5/8),2)*INT(Bang_Tra_Cuu!$L$8/2),2)*2+MOD(MOD(I$5,2)*INT(Bang_Tra_Cuu!$I$8/4)+MOD(INT(I$5/2),2)*INT(Bang_Tra_Cuu!$J$8/4)+MOD(INT(I$5/4),2)*INT(Bang_Tra_Cuu!$K$8/4)+MOD(INT(I$5/8),2)*INT(Bang_Tra_Cuu!$L$8/4),2)*4+MOD(MOD(I$5,2)*INT(Bang_Tra_Cuu!$I$8/8)+MOD(INT(I$5/2),2)*INT(Bang_Tra_Cuu!$J$8/8)+MOD(INT(I$5/4),2)*INT(Bang_Tra_Cuu!$K$8/8)+MOD(INT(I$5/8),2)*INT(Bang_Tra_Cuu!$L$8/8),2)*8 | J9: =MOD(MOD(J$5,2)*INT(Bang_Tra_Cuu!$I$8/1)+MOD(INT(J$5/2),2)*INT(Bang_Tra_Cuu!$J$8/1)+MOD(INT(J$5/4),2)*INT(Bang_Tra_Cuu!$K$8/1)+MOD(INT(J$5/8),2)*INT(Bang_Tra_Cuu!$L$8/1),2)*1+MOD(MOD(J$5,2)*INT(Bang_Tra_Cuu!$I$8/2)+MOD(INT(J$5/2),2)*INT(Bang_Tra_Cuu!$J$8/2)+MOD(INT(J$5/4),2)*INT(Bang_Tra_Cuu!$K$8/2)+MOD(INT(J$5/8),2)*INT(Bang_Tra_Cuu!$L$8/2),2)*2+MOD(MOD(J$5,2)*INT(Bang_Tra_Cuu!$I$8/4)+MOD(INT(J$5/2),2)*INT(Bang_Tra_Cuu!$J$8/4)+MOD(INT(J$5/4),2)*INT(Bang_Tra_Cuu!$K$8/4)+MOD(INT(J$5/8),2)*INT(Bang_Tra_Cuu!$L$8/4),2)*4+MOD(MOD(J$5,2)*INT(Bang_Tra_Cuu!$I$8/8)+MOD(INT(J$5/2),2)*INT(Bang_Tra_Cuu!$J$8/8)+MOD(INT(J$5/4),2)*INT(Bang_Tra_Cuu!$K$8/8)+MOD(INT(J$5/8),2)*INT(Bang_Tra_Cuu!$L$8/8),2)*8 | ... R9: =MOD(MOD(R$5,2)*INT(Bang_Tra_Cuu!$I$8/1)+MOD(INT(R$5/2),2)*INT(Bang_Tra_Cuu!$J$8/1)+MOD(INT(R$5/4),2)*INT(Bang_Tra_Cuu!$K$8/1)+MOD(INT(R$5/8),2)*INT(Bang_Tra_Cuu!$L$8/1),2)*1+MOD(MOD(R$5,2)*INT(Bang_Tra_Cuu!$I$8/2)+MOD(INT(R$5/2),2)*INT(Bang_Tra_Cuu!$J$8/2)+MOD(INT(R$5/4),2)*INT(Bang_Tra_Cuu!$K$8/2)+MOD(INT(R$5/8),2)*INT(Bang_Tra_Cuu!$L$8/2),2)*2+MOD(MOD(R$5,2)*INT(Bang_Tra_Cuu!$I$8/4)+MOD(INT(R$5/2),2)*INT(Bang_Tra_Cuu!$J$8/4)+MOD(INT(R$5/4),2)*INT(Bang_Tra_Cuu!$K$8/4)+MOD(INT(R$5/8),2)*INT(Bang_Tra_Cuu!$L$8/4),2)*4+MOD(MOD(R$5,2)*INT(Bang_Tra_Cuu!$I$8/8)+MOD(INT(R$5/2),2)*INT(Bang_Tra_Cuu!$J$8/8)+MOD(INT(R$5/4),2)*INT(Bang_Tra_Cuu!$K$8/8)+MOD(INT(R$5/8),2)*INT(Bang_Tra_Cuu!$L$8/8),2)*8 | T9: 3 | U9: x + 1 | V9: =COUNTIF($C$6:$R$21, T9) | W9: =COUNTIF($D$7:$R$21, T9)
A10: 4 | B10: x^2 | C10: =MOD(MOD(C$5,2)*INT(Bang_Tra_Cuu!$I$9/1)+MOD(INT(C$5/2),2)*INT(Bang_Tra_Cuu!$J$9/1)+MOD(INT(C$5/4),2)*INT(Bang_Tra_Cuu!$K$9/1)+MOD(INT(C$5/8),2)*INT(Bang_Tra_Cuu!$L$9/1),2)*1+MOD(MOD(C$5,2)*INT(Bang_Tra_Cuu!$I$9/2)+MOD(INT(C$5/2),2)*INT(Bang_Tra_Cuu!$J$9/2)+MOD(INT(C$5/4),2)*INT(Bang_Tra_Cuu!$K$9/2)+MOD(INT(C$5/8),2)*INT(Bang_Tra_Cuu!$L$9/2),2)*2+MOD(MOD(C$5,2)*INT(Bang_Tra_Cuu!$I$9/4)+MOD(INT(C$5/2),2)*INT(Bang_Tra_Cuu!$J$9/4)+MOD(INT(C$5/4),2)*INT(Bang_Tra_Cuu!$K$9/4)+MOD(INT(C$5/8),2)*INT(Bang_Tra_Cuu!$L$9/4),2)*4+MOD(MOD(C$5,2)*INT(Bang_Tra_Cuu!$I$9/8)+MOD(INT(C$5/2),2)*INT(Bang_Tra_Cuu!$J$9/8)+MOD(INT(C$5/4),2)*INT(Bang_Tra_Cuu!$K$9/8)+MOD(INT(C$5/8),2)*INT(Bang_Tra_Cuu!$L$9/8),2)*8 | D10: =MOD(MOD(D$5,2)*INT(Bang_Tra_Cuu!$I$9/1)+MOD(INT(D$5/2),2)*INT(Bang_Tra_Cuu!$J$9/1)+MOD(INT(D$5/4),2)*INT(Bang_Tra_Cuu!$K$9/1)+MOD(INT(D$5/8),2)*INT(Bang_Tra_Cuu!$L$9/1),2)*1+MOD(MOD(D$5,2)*INT(Bang_Tra_Cuu!$I$9/2)+MOD(INT(D$5/2),2)*INT(Bang_Tra_Cuu!$J$9/2)+MOD(INT(D$5/4),2)*INT(Bang_Tra_Cuu!$K$9/2)+MOD(INT(D$5/8),2)*INT(Bang_Tra_Cuu!$L$9/2),2)*2+MOD(MOD(D$5,2)*INT(Bang_Tra_Cuu!$I$9/4)+MOD(INT(D$5/2),2)*INT(Bang_Tra_Cuu!$J$9/4)+MOD(INT(D$5/4),2)*INT(Bang_Tra_Cuu!$K$9/4)+MOD(INT(D$5/8),2)*INT(Bang_Tra_Cuu!$L$9/4),2)*4+MOD(MOD(D$5,2)*INT(Bang_Tra_Cuu!$I$9/8)+MOD(INT(D$5/2),2)*INT(Bang_Tra_Cuu!$J$9/8)+MOD(INT(D$5/4),2)*INT(Bang_Tra_Cuu!$K$9/8)+MOD(INT(D$5/8),2)*INT(Bang_Tra_Cuu!$L$9/8),2)*8 | E10: =MOD(MOD(E$5,2)*INT(Bang_Tra_Cuu!$I$9/1)+MOD(INT(E$5/2),2)*INT(Bang_Tra_Cuu!$J$9/1)+MOD(INT(E$5/4),2)*INT(Bang_Tra_Cuu!$K$9/1)+MOD(INT(E$5/8),2)*INT(Bang_Tra_Cuu!$L$9/1),2)*1+MOD(MOD(E$5,2)*INT(Bang_Tra_Cuu!$I$9/2)+MOD(INT(E$5/2),2)*INT(Bang_Tra_Cuu!$J$9/2)+MOD(INT(E$5/4),2)*INT(Bang_Tra_Cuu!$K$9/2)+MOD(INT(E$5/8),2)*INT(Bang_Tra_Cuu!$L$9/2),2)*2+MOD(MOD(E$5,2)*INT(Bang_Tra_Cuu!$I$9/4)+MOD(INT(E$5/2),2)*INT(Bang_Tra_Cuu!$J$9/4)+MOD(INT(E$5/4),2)*INT(Bang_Tra_Cuu!$K$9/4)+MOD(INT(E$5/8),2)*INT(Bang_Tra_Cuu!$L$9/4),2)*4+MOD(MOD(E$5,2)*INT(Bang_Tra_Cuu!$I$9/8)+MOD(INT(E$5/2),2)*INT(Bang_Tra_Cuu!$J$9/8)+MOD(INT(E$5/4),2)*INT(Bang_Tra_Cuu!$K$9/8)+MOD(INT(E$5/8),2)*INT(Bang_Tra_Cuu!$L$9/8),2)*8 | F10: =MOD(MOD(F$5,2)*INT(Bang_Tra_Cuu!$I$9/1)+MOD(INT(F$5/2),2)*INT(Bang_Tra_Cuu!$J$9/1)+MOD(INT(F$5/4),2)*INT(Bang_Tra_Cuu!$K$9/1)+MOD(INT(F$5/8),2)*INT(Bang_Tra_Cuu!$L$9/1),2)*1+MOD(MOD(F$5,2)*INT(Bang_Tra_Cuu!$I$9/2)+MOD(INT(F$5/2),2)*INT(Bang_Tra_Cuu!$J$9/2)+MOD(INT(F$5/4),2)*INT(Bang_Tra_Cuu!$K$9/2)+MOD(INT(F$5/8),2)*INT(Bang_Tra_Cuu!$L$9/2),2)*2+MOD(MOD(F$5,2)*INT(Bang_Tra_Cuu!$I$9/4)+MOD(INT(F$5/2),2)*INT(Bang_Tra_Cuu!$J$9/4)+MOD(INT(F$5/4),2)*INT(Bang_Tra_Cuu!$K$9/4)+MOD(INT(F$5/8),2)*INT(Bang_Tra_Cuu!$L$9/4),2)*4+MOD(MOD(F$5,2)*INT(Bang_Tra_Cuu!$I$9/8)+MOD(INT(F$5/2),2)*INT(Bang_Tra_Cuu!$J$9/8)+MOD(INT(F$5/4),2)*INT(Bang_Tra_Cuu!$K$9/8)+MOD(INT(F$5/8),2)*INT(Bang_Tra_Cuu!$L$9/8),2)*8 | G10: =MOD(MOD(G$5,2)*INT(Bang_Tra_Cuu!$I$9/1)+MOD(INT(G$5/2),2)*INT(Bang_Tra_Cuu!$J$9/1)+MOD(INT(G$5/4),2)*INT(Bang_Tra_Cuu!$K$9/1)+MOD(INT(G$5/8),2)*INT(Bang_Tra_Cuu!$L$9/1),2)*1+MOD(MOD(G$5,2)*INT(Bang_Tra_Cuu!$I$9/2)+MOD(INT(G$5/2),2)*INT(Bang_Tra_Cuu!$J$9/2)+MOD(INT(G$5/4),2)*INT(Bang_Tra_Cuu!$K$9/2)+MOD(INT(G$5/8),2)*INT(Bang_Tra_Cuu!$L$9/2),2)*2+MOD(MOD(G$5,2)*INT(Bang_Tra_Cuu!$I$9/4)+MOD(INT(G$5/2),2)*INT(Bang_Tra_Cuu!$J$9/4)+MOD(INT(G$5/4),2)*INT(Bang_Tra_Cuu!$K$9/4)+MOD(INT(G$5/8),2)*INT(Bang_Tra_Cuu!$L$9/4),2)*4+MOD(MOD(G$5,2)*INT(Bang_Tra_Cuu!$I$9/8)+MOD(INT(G$5/2),2)*INT(Bang_Tra_Cuu!$J$9/8)+MOD(INT(G$5/4),2)*INT(Bang_Tra_Cuu!$K$9/8)+MOD(INT(G$5/8),2)*INT(Bang_Tra_Cuu!$L$9/8),2)*8 | H10: =MOD(MOD(H$5,2)*INT(Bang_Tra_Cuu!$I$9/1)+MOD(INT(H$5/2),2)*INT(Bang_Tra_Cuu!$J$9/1)+MOD(INT(H$5/4),2)*INT(Bang_Tra_Cuu!$K$9/1)+MOD(INT(H$5/8),2)*INT(Bang_Tra_Cuu!$L$9/1),2)*1+MOD(MOD(H$5,2)*INT(Bang_Tra_Cuu!$I$9/2)+MOD(INT(H$5/2),2)*INT(Bang_Tra_Cuu!$J$9/2)+MOD(INT(H$5/4),2)*INT(Bang_Tra_Cuu!$K$9/2)+MOD(INT(H$5/8),2)*INT(Bang_Tra_Cuu!$L$9/2),2)*2+MOD(MOD(H$5,2)*INT(Bang_Tra_Cuu!$I$9/4)+MOD(INT(H$5/2),2)*INT(Bang_Tra_Cuu!$J$9/4)+MOD(INT(H$5/4),2)*INT(Bang_Tra_Cuu!$K$9/4)+MOD(INT(H$5/8),2)*INT(Bang_Tra_Cuu!$L$9/4),2)*4+MOD(MOD(H$5,2)*INT(Bang_Tra_Cuu!$I$9/8)+MOD(INT(H$5/2),2)*INT(Bang_Tra_Cuu!$J$9/8)+MOD(INT(H$5/4),2)*INT(Bang_Tra_Cuu!$K$9/8)+MOD(INT(H$5/8),2)*INT(Bang_Tra_Cuu!$L$9/8),2)*8 | I10: =MOD(MOD(I$5,2)*INT(Bang_Tra_Cuu!$I$9/1)+MOD(INT(I$5/2),2)*INT(Bang_Tra_Cuu!$J$9/1)+MOD(INT(I$5/4),2)*INT(Bang_Tra_Cuu!$K$9/1)+MOD(INT(I$5/8),2)*INT(Bang_Tra_Cuu!$L$9/1),2)*1+MOD(MOD(I$5,2)*INT(Bang_Tra_Cuu!$I$9/2)+MOD(INT(I$5/2),2)*INT(Bang_Tra_Cuu!$J$9/2)+MOD(INT(I$5/4),2)*INT(Bang_Tra_Cuu!$K$9/2)+MOD(INT(I$5/8),2)*INT(Bang_Tra_Cuu!$L$9/2),2)*2+MOD(MOD(I$5,2)*INT(Bang_Tra_Cuu!$I$9/4)+MOD(INT(I$5/2),2)*INT(Bang_Tra_Cuu!$J$9/4)+MOD(INT(I$5/4),2)*INT(Bang_Tra_Cuu!$K$9/4)+MOD(INT(I$5/8),2)*INT(Bang_Tra_Cuu!$L$9/4),2)*4+MOD(MOD(I$5,2)*INT(Bang_Tra_Cuu!$I$9/8)+MOD(INT(I$5/2),2)*INT(Bang_Tra_Cuu!$J$9/8)+MOD(INT(I$5/4),2)*INT(Bang_Tra_Cuu!$K$9/8)+MOD(INT(I$5/8),2)*INT(Bang_Tra_Cuu!$L$9/8),2)*8 | J10: =MOD(MOD(J$5,2)*INT(Bang_Tra_Cuu!$I$9/1)+MOD(INT(J$5/2),2)*INT(Bang_Tra_Cuu!$J$9/1)+MOD(INT(J$5/4),2)*INT(Bang_Tra_Cuu!$K$9/1)+MOD(INT(J$5/8),2)*INT(Bang_Tra_Cuu!$L$9/1),2)*1+MOD(MOD(J$5,2)*INT(Bang_Tra_Cuu!$I$9/2)+MOD(INT(J$5/2),2)*INT(Bang_Tra_Cuu!$J$9/2)+MOD(INT(J$5/4),2)*INT(Bang_Tra_Cuu!$K$9/2)+MOD(INT(J$5/8),2)*INT(Bang_Tra_Cuu!$L$9/2),2)*2+MOD(MOD(J$5,2)*INT(Bang_Tra_Cuu!$I$9/4)+MOD(INT(J$5/2),2)*INT(Bang_Tra_Cuu!$J$9/4)+MOD(INT(J$5/4),2)*INT(Bang_Tra_Cuu!$K$9/4)+MOD(INT(J$5/8),2)*INT(Bang_Tra_Cuu!$L$9/4),2)*4+MOD(MOD(J$5,2)*INT(Bang_Tra_Cuu!$I$9/8)+MOD(INT(J$5/2),2)*INT(Bang_Tra_Cuu!$J$9/8)+MOD(INT(J$5/4),2)*INT(Bang_Tra_Cuu!$K$9/8)+MOD(INT(J$5/8),2)*INT(Bang_Tra_Cuu!$L$9/8),2)*8 | ... R10: =MOD(MOD(R$5,2)*INT(Bang_Tra_Cuu!$I$9/1)+MOD(INT(R$5/2),2)*INT(Bang_Tra_Cuu!$J$9/1)+MOD(INT(R$5/4),2)*INT(Bang_Tra_Cuu!$K$9/1)+MOD(INT(R$5/8),2)*INT(Bang_Tra_Cuu!$L$9/1),2)*1+MOD(MOD(R$5,2)*INT(Bang_Tra_Cuu!$I$9/2)+MOD(INT(R$5/2),2)*INT(Bang_Tra_Cuu!$J$9/2)+MOD(INT(R$5/4),2)*INT(Bang_Tra_Cuu!$K$9/2)+MOD(INT(R$5/8),2)*INT(Bang_Tra_Cuu!$L$9/2),2)*2+MOD(MOD(R$5,2)*INT(Bang_Tra_Cuu!$I$9/4)+MOD(INT(R$5/2),2)*INT(Bang_Tra_Cuu!$J$9/4)+MOD(INT(R$5/4),2)*INT(Bang_Tra_Cuu!$K$9/4)+MOD(INT(R$5/8),2)*INT(Bang_Tra_Cuu!$L$9/4),2)*4+MOD(MOD(R$5,2)*INT(Bang_Tra_Cuu!$I$9/8)+MOD(INT(R$5/2),2)*INT(Bang_Tra_Cuu!$J$9/8)+MOD(INT(R$5/4),2)*INT(Bang_Tra_Cuu!$K$9/8)+MOD(INT(R$5/8),2)*INT(Bang_Tra_Cuu!$L$9/8),2)*8 | T10: 4 | U10: x^2 | V10: =COUNTIF($C$6:$R$21, T10) | W10: =COUNTIF($D$7:$R$21, T10)
A11: 5 | B11: x^2 + 1 | C11: =MOD(MOD(C$5,2)*INT(Bang_Tra_Cuu!$I$10/1)+MOD(INT(C$5/2),2)*INT(Bang_Tra_Cuu!$J$10/1)+MOD(INT(C$5/4),2)*INT(Bang_Tra_Cuu!$K$10/1)+MOD(INT(C$5/8),2)*INT(Bang_Tra_Cuu!$L$10/1),2)*1+MOD(MOD(C$5,2)*INT(Bang_Tra_Cuu!$I$10/2)+MOD(INT(C$5/2),2)*INT(Bang_Tra_Cuu!$J$10/2)+MOD(INT(C$5/4),2)*INT(Bang_Tra_Cuu!$K$10/2)+MOD(INT(C$5/8),2)*INT(Bang_Tra_Cuu!$L$10/2),2)*2+MOD(MOD(C$5,2)*INT(Bang_Tra_Cuu!$I$10/4)+MOD(INT(C$5/2),2)*INT(Bang_Tra_Cuu!$J$10/4)+MOD(INT(C$5/4),2)*INT(Bang_Tra_Cuu!$K$10/4)+MOD(INT(C$5/8),2)*INT(Bang_Tra_Cuu!$L$10/4),2)*4+MOD(MOD(C$5,2)*INT(Bang_Tra_Cuu!$I$10/8)+MOD(INT(C$5/2),2)*INT(Bang_Tra_Cuu!$J$10/8)+MOD(INT(C$5/4),2)*INT(Bang_Tra_Cuu!$K$10/8)+MOD(INT(C$5/8),2)*INT(Bang_Tra_Cuu!$L$10/8),2)*8 | D11: =MOD(MOD(D$5,2)*INT(Bang_Tra_Cuu!$I$10/1)+MOD(INT(D$5/2),2)*INT(Bang_Tra_Cuu!$J$10/1)+MOD(INT(D$5/4),2)*INT(Bang_Tra_Cuu!$K$10/1)+MOD(INT(D$5/8),2)*INT(Bang_Tra_Cuu!$L$10/1),2)*1+MOD(MOD(D$5,2)*INT(Bang_Tra_Cuu!$I$10/2)+MOD(INT(D$5/2),2)*INT(Bang_Tra_Cuu!$J$10/2)+MOD(INT(D$5/4),2)*INT(Bang_Tra_Cuu!$K$10/2)+MOD(INT(D$5/8),2)*INT(Bang_Tra_Cuu!$L$10/2),2)*2+MOD(MOD(D$5,2)*INT(Bang_Tra_Cuu!$I$10/4)+MOD(INT(D$5/2),2)*INT(Bang_Tra_Cuu!$J$10/4)+MOD(INT(D$5/4),2)*INT(Bang_Tra_Cuu!$K$10/4)+MOD(INT(D$5/8),2)*INT(Bang_Tra_Cuu!$L$10/4),2)*4+MOD(MOD(D$5,2)*INT(Bang_Tra_Cuu!$I$10/8)+MOD(INT(D$5/2),2)*INT(Bang_Tra_Cuu!$J$10/8)+MOD(INT(D$5/4),2)*INT(Bang_Tra_Cuu!$K$10/8)+MOD(INT(D$5/8),2)*INT(Bang_Tra_Cuu!$L$10/8),2)*8 | E11: =MOD(MOD(E$5,2)*INT(Bang_Tra_Cuu!$I$10/1)+MOD(INT(E$5/2),2)*INT(Bang_Tra_Cuu!$J$10/1)+MOD(INT(E$5/4),2)*INT(Bang_Tra_Cuu!$K$10/1)+MOD(INT(E$5/8),2)*INT(Bang_Tra_Cuu!$L$10/1),2)*1+MOD(MOD(E$5,2)*INT(Bang_Tra_Cuu!$I$10/2)+MOD(INT(E$5/2),2)*INT(Bang_Tra_Cuu!$J$10/2)+MOD(INT(E$5/4),2)*INT(Bang_Tra_Cuu!$K$10/2)+MOD(INT(E$5/8),2)*INT(Bang_Tra_Cuu!$L$10/2),2)*2+MOD(MOD(E$5,2)*INT(Bang_Tra_Cuu!$I$10/4)+MOD(INT(E$5/2),2)*INT(Bang_Tra_Cuu!$J$10/4)+MOD(INT(E$5/4),2)*INT(Bang_Tra_Cuu!$K$10/4)+MOD(INT(E$5/8),2)*INT(Bang_Tra_Cuu!$L$10/4),2)*4+MOD(MOD(E$5,2)*INT(Bang_Tra_Cuu!$I$10/8)+MOD(INT(E$5/2),2)*INT(Bang_Tra_Cuu!$J$10/8)+MOD(INT(E$5/4),2)*INT(Bang_Tra_Cuu!$K$10/8)+MOD(INT(E$5/8),2)*INT(Bang_Tra_Cuu!$L$10/8),2)*8 | F11: =MOD(MOD(F$5,2)*INT(Bang_Tra_Cuu!$I$10/1)+MOD(INT(F$5/2),2)*INT(Bang_Tra_Cuu!$J$10/1)+MOD(INT(F$5/4),2)*INT(Bang_Tra_Cuu!$K$10/1)+MOD(INT(F$5/8),2)*INT(Bang_Tra_Cuu!$L$10/1),2)*1+MOD(MOD(F$5,2)*INT(Bang_Tra_Cuu!$I$10/2)+MOD(INT(F$5/2),2)*INT(Bang_Tra_Cuu!$J$10/2)+MOD(INT(F$5/4),2)*INT(Bang_Tra_Cuu!$K$10/2)+MOD(INT(F$5/8),2)*INT(Bang_Tra_Cuu!$L$10/2),2)*2+MOD(MOD(F$5,2)*INT(Bang_Tra_Cuu!$I$10/4)+MOD(INT(F$5/2),2)*INT(Bang_Tra_Cuu!$J$10/4)+MOD(INT(F$5/4),2)*INT(Bang_Tra_Cuu!$K$10/4)+MOD(INT(F$5/8),2)*INT(Bang_Tra_Cuu!$L$10/4),2)*4+MOD(MOD(F$5,2)*INT(Bang_Tra_Cuu!$I$10/8)+MOD(INT(F$5/2),2)*INT(Bang_Tra_Cuu!$J$10/8)+MOD(INT(F$5/4),2)*INT(Bang_Tra_Cuu!$K$10/8)+MOD(INT(F$5/8),2)*INT(Bang_Tra_Cuu!$L$10/8),2)*8 | G11: =MOD(MOD(G$5,2)*INT(Bang_Tra_Cuu!$I$10/1)+MOD(INT(G$5/2),2)*INT(Bang_Tra_Cuu!$J$10/1)+MOD(INT(G$5/4),2)*INT(Bang_Tra_Cuu!$K$10/1)+MOD(INT(G$5/8),2)*INT(Bang_Tra_Cuu!$L$10/1),2)*1+MOD(MOD(G$5,2)*INT(Bang_Tra_Cuu!$I$10/2)+MOD(INT(G$5/2),2)*INT(Bang_Tra_Cuu!$J$10/2)+MOD(INT(G$5/4),2)*INT(Bang_Tra_Cuu!$K$10/2)+MOD(INT(G$5/8),2)*INT(Bang_Tra_Cuu!$L$10/2),2)*2+MOD(MOD(G$5,2)*INT(Bang_Tra_Cuu!$I$10/4)+MOD(INT(G$5/2),2)*INT(Bang_Tra_Cuu!$J$10/4)+MOD(INT(G$5/4),2)*INT(Bang_Tra_Cuu!$K$10/4)+MOD(INT(G$5/8),2)*INT(Bang_Tra_Cuu!$L$10/4),2)*4+MOD(MOD(G$5,2)*INT(Bang_Tra_Cuu!$I$10/8)+MOD(INT(G$5/2),2)*INT(Bang_Tra_Cuu!$J$10/8)+MOD(INT(G$5/4),2)*INT(Bang_Tra_Cuu!$K$10/8)+MOD(INT(G$5/8),2)*INT(Bang_Tra_Cuu!$L$10/8),2)*8 | H11: =MOD(MOD(H$5,2)*INT(Bang_Tra_Cuu!$I$10/1)+MOD(INT(H$5/2),2)*INT(Bang_Tra_Cuu!$J$10/1)+MOD(INT(H$5/4),2)*INT(Bang_Tra_Cuu!$K$10/1)+MOD(INT(H$5/8),2)*INT(Bang_Tra_Cuu!$L$10/1),2)*1+MOD(MOD(H$5,2)*INT(Bang_Tra_Cuu!$I$10/2)+MOD(INT(H$5/2),2)*INT(Bang_Tra_Cuu!$J$10/2)+MOD(INT(H$5/4),2)*INT(Bang_Tra_Cuu!$K$10/2)+MOD(INT(H$5/8),2)*INT(Bang_Tra_Cuu!$L$10/2),2)*2+MOD(MOD(H$5,2)*INT(Bang_Tra_Cuu!$I$10/4)+MOD(INT(H$5/2),2)*INT(Bang_Tra_Cuu!$J$10/4)+MOD(INT(H$5/4),2)*INT(Bang_Tra_Cuu!$K$10/4)+MOD(INT(H$5/8),2)*INT(Bang_Tra_Cuu!$L$10/4),2)*4+MOD(MOD(H$5,2)*INT(Bang_Tra_Cuu!$I$10/8)+MOD(INT(H$5/2),2)*INT(Bang_Tra_Cuu!$J$10/8)+MOD(INT(H$5/4),2)*INT(Bang_Tra_Cuu!$K$10/8)+MOD(INT(H$5/8),2)*INT(Bang_Tra_Cuu!$L$10/8),2)*8 | I11: =MOD(MOD(I$5,2)*INT(Bang_Tra_Cuu!$I$10/1)+MOD(INT(I$5/2),2)*INT(Bang_Tra_Cuu!$J$10/1)+MOD(INT(I$5/4),2)*INT(Bang_Tra_Cuu!$K$10/1)+MOD(INT(I$5/8),2)*INT(Bang_Tra_Cuu!$L$10/1),2)*1+MOD(MOD(I$5,2)*INT(Bang_Tra_Cuu!$I$10/2)+MOD(INT(I$5/2),2)*INT(Bang_Tra_Cuu!$J$10/2)+MOD(INT(I$5/4),2)*INT(Bang_Tra_Cuu!$K$10/2)+MOD(INT(I$5/8),2)*INT(Bang_Tra_Cuu!$L$10/2),2)*2+MOD(MOD(I$5,2)*INT(Bang_Tra_Cuu!$I$10/4)+MOD(INT(I$5/2),2)*INT(Bang_Tra_Cuu!$J$10/4)+MOD(INT(I$5/4),2)*INT(Bang_Tra_Cuu!$K$10/4)+MOD(INT(I$5/8),2)*INT(Bang_Tra_Cuu!$L$10/4),2)*4+MOD(MOD(I$5,2)*INT(Bang_Tra_Cuu!$I$10/8)+MOD(INT(I$5/2),2)*INT(Bang_Tra_Cuu!$J$10/8)+MOD(INT(I$5/4),2)*INT(Bang_Tra_Cuu!$K$10/8)+MOD(INT(I$5/8),2)*INT(Bang_Tra_Cuu!$L$10/8),2)*8 | J11: =MOD(MOD(J$5,2)*INT(Bang_Tra_Cuu!$I$10/1)+MOD(INT(J$5/2),2)*INT(Bang_Tra_Cuu!$J$10/1)+MOD(INT(J$5/4),2)*INT(Bang_Tra_Cuu!$K$10/1)+MOD(INT(J$5/8),2)*INT(Bang_Tra_Cuu!$L$10/1),2)*1+MOD(MOD(J$5,2)*INT(Bang_Tra_Cuu!$I$10/2)+MOD(INT(J$5/2),2)*INT(Bang_Tra_Cuu!$J$10/2)+MOD(INT(J$5/4),2)*INT(Bang_Tra_Cuu!$K$10/2)+MOD(INT(J$5/8),2)*INT(Bang_Tra_Cuu!$L$10/2),2)*2+MOD(MOD(J$5,2)*INT(Bang_Tra_Cuu!$I$10/4)+MOD(INT(J$5/2),2)*INT(Bang_Tra_Cuu!$J$10/4)+MOD(INT(J$5/4),2)*INT(Bang_Tra_Cuu!$K$10/4)+MOD(INT(J$5/8),2)*INT(Bang_Tra_Cuu!$L$10/4),2)*4+MOD(MOD(J$5,2)*INT(Bang_Tra_Cuu!$I$10/8)+MOD(INT(J$5/2),2)*INT(Bang_Tra_Cuu!$J$10/8)+MOD(INT(J$5/4),2)*INT(Bang_Tra_Cuu!$K$10/8)+MOD(INT(J$5/8),2)*INT(Bang_Tra_Cuu!$L$10/8),2)*8 | ... R11: =MOD(MOD(R$5,2)*INT(Bang_Tra_Cuu!$I$10/1)+MOD(INT(R$5/2),2)*INT(Bang_Tra_Cuu!$J$10/1)+MOD(INT(R$5/4),2)*INT(Bang_Tra_Cuu!$K$10/1)+MOD(INT(R$5/8),2)*INT(Bang_Tra_Cuu!$L$10/1),2)*1+MOD(MOD(R$5,2)*INT(Bang_Tra_Cuu!$I$10/2)+MOD(INT(R$5/2),2)*INT(Bang_Tra_Cuu!$J$10/2)+MOD(INT(R$5/4),2)*INT(Bang_Tra_Cuu!$K$10/2)+MOD(INT(R$5/8),2)*INT(Bang_Tra_Cuu!$L$10/2),2)*2+MOD(MOD(R$5,2)*INT(Bang_Tra_Cuu!$I$10/4)+MOD(INT(R$5/2),2)*INT(Bang_Tra_Cuu!$J$10/4)+MOD(INT(R$5/4),2)*INT(Bang_Tra_Cuu!$K$10/4)+MOD(INT(R$5/8),2)*INT(Bang_Tra_Cuu!$L$10/4),2)*4+MOD(MOD(R$5,2)*INT(Bang_Tra_Cuu!$I$10/8)+MOD(INT(R$5/2),2)*INT(Bang_Tra_Cuu!$J$10/8)+MOD(INT(R$5/4),2)*INT(Bang_Tra_Cuu!$K$10/8)+MOD(INT(R$5/8),2)*INT(Bang_Tra_Cuu!$L$10/8),2)*8 | T11: 5 | U11: x^2 + 1 | V11: =COUNTIF($C$6:$R$21, T11) | W11: =COUNTIF($D$7:$R$21, T11)
